Workbook
Name \z: #REF!
Name ___agg10: #N/A
Name ___agg20: #N/A
Name ___CAN112: 13.42
Name ___CAN113: 12.98
Name ___CAN117: 12.7
Name ___CAN118: 13.27
Name ___CAN120: 11.72
Name ___CAN210: 10.38
Name ___CAN211: 10.58
Name ___CAN213: 10.56
Name ___CAN215: 10.22
Name ___CAN216: 9.61
Name ___CAN217: 10.47
Name ___CAN219: 10.91
Name ___CAN220: 11.09
Name ___CAN221: 11.25
Name ___CAN222: 10.17
Name ___CAN223: 9.89
Name ___CAN230: 10.79
Name ___can421: 40.2
Name ___can422: 41.57
Name ___can423: 43.9
Name ___can424: 41.19
Name ___can425: 42.81
Name ___can426: 40.77
Name ___can427: 40.92
Name ___can428: 39.29
Name ___can429: 45.19
Name ___can430: 40.73
Name ___can431: 42.52
Name ___can432: 42.53
Name ___can433: 43.69
Name ___can434: 40.43
Name ___can435: 43.3
Name ___hmp100: #N/A
Name ___hmp120: #N/A
Name ___HND1: #N/A
Name ___HND2: #N/A
Name ___HNW1: #N/A
Name ___HNW2: #N/A
Name ___Ind1: #N/A
Name ___Ind3: #N/A
Name ___Ind4: #N/A
Name ___Iri2: #N/A
Name ___Iro2: #N/A
Name ___obm1: #N/A
Name ___obm2: #N/A
Name ___obm3: #N/A
Name ___obm4: #N/A
Name ___Od1: #N/A
Name ___Od3: #N/A
Name ___Od4: #N/A
Name ___osf1: #N/A
Name ___osf2: #N/A
Name ___osf3: #N/A
Name ___osf4: #N/A
Name ___pvc100: #N/A
Name ___sbm1: #N/A
Name ___sbm2: #N/A

Sheet Grand summary 
A1: Provident Botanica, Samethanahalli, Bangalore.
A2: Structure & Finishing Works
A3: Sl.No. | B3: Description | C3: As per VO#01 | D3: As per Actual | E3: Present Variation
C5: Amount (Rs.)
A6: A | B6: CIVIL & STRUCTURAL WORKS
A7: 1 | B7: Earthwork & Antitermite Works | C7: 16107268 | D7: ='Part-A & B_BOQ '!H34+'Part-A & B_BOQ '!H38 -> 0 | E7: =D7+C7 -> 16107268 | J7: 21706453 | L7: =D7-J7 -> -21706453
A8: =A7+1 -> 2 | B8: Plain cement concrete works | C8: 28217791 | D8: ='Part-A & B_BOQ '!$H$60 -> 0 | E8: =D8+C8 -> 28217791 | J8: 28217815 | L8: =D8-J8 -> -28217815
A9: =A8+1 -> 3 | B9: Reinforced cement concrete works | C9: 6.3666169e+08 | D9: ='Part-A & B_BOQ '!$H$349 -> 0 | E9: =D9+C9 -> 6.3666169e+08 | J9: 6.4073192e+08 | L9: =D9-J9 -> -6.4073192e+08
A10: =A9+1 -> 4 | B10: Form work | C10: 5.1996734e+08 | D10: ='Part-A & B_BOQ '!$H$486 -> 0 | E10: =D10+C10 -> 5.1996734e+08 | J10: 5.2012134e+08 | L10: =D10-J10 -> -5.2012134e+08
A11: =A10+1 -> 5 | B11: Reinforcement Steel Works | C11: 729720015 | D11: ='Part-A & B_BOQ '!$H$520 -> 0 | E11: =D11+C11 -> 729720015 | J11: 729720015 | L11: =D11-J11 -> -729720015
A12: =A11+1 -> 6 | B12: Concrete Flooring works | C12: 85598862 | D12: ='Part-A & B_BOQ '!$H$572 -> 0 | E12: =D12+C12 -> 85598862 | J12: 85598862 | L12: =D12-J12 -> -85598862
A13: =A12+1 -> 7 | B13: Waterproofing works | C13: 122161309 | D13: ='Part-A & B_BOQ '!$H$652 -> 0 | E13: =D13+C13 -> 122161309 | J13: 122161309 | L13: =D13-J13 -> -122161309
A14: =A13+1 -> 8 | B14: Expansion Joints | C14: 25833910 | D14: ='Part-A & B_BOQ '!$H$706 -> 0 | E14: =D14+C14 -> 25833910 | J14: 25833910 | L14: =D14-J14 -> -25833910
A15: =A14+1 -> 9 | B15: Miscellaneous works | C15: 8982055 | D15: ='Part-A & B_BOQ '!$H$784 -> 0 | E15: =D15+C15 -> 8982055 | J15: 8982055 | L15: =D15-J15 -> -8982055
A16: =A15+1 -> 10 | B16: Conduit with accessories | C16: 24362630 | D16: ='Part-A & B_BOQ '!$H$831 -> 0 | E16: =D16+C16 -> 24362630 | J16: 24362630 | L16: =D16-J16 -> -24362630
A17: =A16+1 -> 11 | B17: Masonry works | C17: 19477735 | D17: ='Part-A & B_BOQ '!$H$916 -> 0 | E17: =D17+C17 -> 19477735 | J17: 19477735 | L17: =D17-J17 -> -19477735
A18: =A17+1 -> 12 | B18: Plastering works | C18: 46436588 | D18: ='Part-A & B_BOQ '!$H$1095 -> 0 | E18: =D18+C18 -> 46436588 | J18: 46436588 | L18: =D18-J18 -> -46436588
B19: Sub-Total | C19: =SUM(C7:C18) -> 2.2635272e+09 | D19: =SUM(D7:D18) -> 0 | E19: =SUM(E7:E18) -> 2.2635272e+09 | J19: =SUM(J7:J18) -> 2.2733506e+09 | L19: =SUM(L7:L18) -> -2.2733506e+09
A20: B | B20: FINISHING WORKS | L20: =D20-J20 -> 0
A21: 1 | B21: Gypsum Plastering works | C21: 80879463 | D21: ='Part-A & B_BOQ '!$H$1166 -> 0 | E21: =D21+C21 -> 80879463 | J21: 80879463 | L21: =D21-J21 -> -80879463
A22: 2 | B22: Painting works | C22: 138465821 | D22: ='Part-A & B_BOQ '!$H$1343 -> 0 | E22: =D22+C22 -> 138465821 | J22: 138465821 | L22: =D22-J22 -> -138465821
A23: 3 | B23: Flooring, Dadoing, Skirting works | C23: 298669783 | D23: ='Part-A & B_BOQ '!$H$1935 -> 0 | E23: =D23+C23 -> 298669783 | J23: 298669783 | L23: =D23-J23 -> -298669783
A24: 4 | B24: Structural Steel works | C24: 27158421 | D24: ='Part-A & B_BOQ '!$H$2038 -> 0 | E24: =D24+C24 -> 27158421 | J24: 27158421 | L24: =D24-J24 -> -27158421
A25: 5 | B25: Miscellaneous works | C25: 43257223 | D25: ='Part-A & B_BOQ '!$H$2069 -> -2351580 | E25: =D25+C25 -> 40905643 | J25: 43257223 | L25: =D25-J25 -> -45608803
A26: 6 | B26: Joinery works | C26: 128956950 | D26: ='Part-A & B_BOQ '!$H$2281 -> 0 | E26: =D26+C26 -> 128956950 | J26: 128956950 | L26: =D26-J26 -> -128956950
A27: 7 | B27: UPVC Works | C27: 106523340 | D27: ='Part-A & B_BOQ '!$H$2614 -> 0 | E27: =D27+C27 -> 106523340 | J27: 106523340 | L27: =D27-J27 -> -106523340
A28: 8 | B28: False ceiling works | C28: 9511224 | D28: ='Part-A & B_BOQ '!$H$2652 -> 0 | E28: =D28+C28 -> 9511224 | J28: 9511224 | L28: =D28-J28 -> -9511224
B29: Sub-Total | C29: =SUM(C21:C28) -> 833422225 | D29: =SUM(D21:D28) -> -2351580 | E29: =SUM(E21:E28) -> 831070645 | J29: =SUM(J21:J28) -> 833422225 | L29: =D29-J29 -> -835773805
A30: C | B30: Performance Incentive Payment
A31: 1 | B31: Completion of Terrace Slab (Each Tower) | C31: 69999998 | D31: ='Part-A & B_BOQ '!$H$2652 -> 0 | E31: =D31+C31 -> 69999998
A32: 2 | B32: Completion of Flooring, Internal Painitng & Joinery Works | C32: 50000002 | D32: ='Part-A & B_BOQ '!$H$2652 -> 0 | E32: =D32+C32 -> 50000002
B33: Sub-Total | C33: =SUM(C31:C32) -> 1.2e+08 | D33: =SUM(D31:D32) -> 0 | E33: =SUM(E31:E32) -> 1.2e+08 | J33: =SUM(J32:J32) -> 0 | L33: =D33-J33 -> 0
A34: D | B34: Derived Items | C34: ='Derived Items'!F69 -> 1.160395e+08 | D34: ='Part-A & B_BOQ '!$H$2652 -> 0 | E34: =D34+C34 -> 1.160395e+08 | J34: 1.2126816e+08 | L34: =D34-J34 -> -1.2126816e+08
B35: Sub-Total | C35: =SUM(C34:C34) -> 1.160395e+08 | D35: =SUM(D34:D34) -> 0 | E35: =SUM(E34:E34) -> 1.160395e+08 | J35: =SUM(J34:J34) -> 1.2126816e+08 | L35: =D35-J35 -> -1.2126816e+08
A36: E | B36: NT Items | D36: ='NT#01'!F21 -> 8182316.5 | E36: =D36+C36 -> 8182316.5
B37: Sub-Total | D37: =SUM(D36) -> 8182316.5 | E37: =SUM(E36) -> 8182316.5
B38: Total Amount (Excl GST) | C38: =C19+C29+C35+C33+C37 -> 3.3329889e+09 | D38: =D19+D29+D35+D33+D37 -> 5830736.5 | E38: =E19+E29+E35+E33+E37 -> 3.3388197e+09 | J38: =J19+J29+J35+#REF! -> #REF! | L38: =L19+L29+L35+#REF! -> #REF!

Sheet Part-A & B_BOQ 
A1: BOQ FOR CIVIL & FINISHING WORKS
A3: Item No. | B3: Description of works | C3: UOM | D3: Rate | E3: As per VO#01 | G3: As per Actual | I3: Present Variation | K3: Remarks
E4: Qty | F4: Amount | G4: Qty | H4: Amount | I4: Qty | J4: Amount
A5: A | B5: STRUCTURE WORKS
E6: 0 | F6: =ROUND(E6*D6,0) -> 0
A7: 1 | B7: EARTH WORKS | E7: 0 | F7: =ROUND(E7*D7,0) -> 0 | K7: =IFERROR(#REF!/E7,0) -> 0
B8: General Notes for all Excavation Items: Contractor shall take all required permissions from the appropriate authorities for Excavation, Blasting, Carting away materials etc. and shall bear all the expenses for the same. | E8: 0 | F8: =ROUND(E8*D8,0) -> 0 | K8: =IFERROR(#REF!/E8,0) -> 0
B9: Rate shall include 1. Removal of all kinds of vegetation, small shrubs etc. If there are any shrubs, bushes, roots of the trees to be removed for min depth 1.5m including all necessary permissions. Lift & lead outside campus are to be considered to suit the local regulations. The necessary approval shall be taken for removal of trees with the consent of the clients if applicable. The contractor shall be fully responsible for liasoning with local authoritites, compliance to all the statutory obligations, including all labour lanes in force, facilities, policies etc. towards all employees , labour and under no circumstance nor any acting party pass on the responsiblitites of the contractor to the other contractor/clients. | E9: 0 | F9: =ROUND(E9*D9,0) -> 0 | K9: =IFERROR(#REF!/E9,0) -> 0
B10: 2. Contractor shall get acquainted with site conditions, nature of soil and adopt suitable dewatering system as deemed fit for the nature of soil and prevailing water table and water collected by runoff or rain needs to be disposed off from the site. The rate shall include keeping the excavated surface dry till completion of the scope of work. Dewatered water/ Slush shall be drained out by suitable means to places not objected by civic authorities. The contractor shall submit the method statement for dewatering and the same shall be let out of the building premises through proper pipes & channels as required. | E10: 0 | F10: =ROUND(E10*D10,0) -> 0 | K10: =IFERROR(#REF!/E10,0) -> 0
B11: 3. The rate shall include necessary general shoring, strutting with approved timber/steel accessories wherever necessary as approved by the Client / the Engineer. | D11: 0 | E11: 0 | F11: =ROUND(E11*D11,0) -> 0 | K11: =IFERROR(#REF!/E11,0) -> 0
B12: 4. Contour level to be taken jointly with the Project Manager and prior written approval be taken before starting any excavation/ filling at every 5 mt grids for arriving at the actual quantity using simpsons rule. Cost to include all and necessary royalty and other permission charges required to execute the works. | D12: 0 | E12: 0 | F12: =ROUND(E12*D12,0) -> 0 | K12: =IFERROR(#REF!/E12,0) -> 0
B13: 5. The rate shall include all necessary setting out of building, excavation line, barrication by grid/plot marking, survey by Total station, transfer of bench mark, etc., complete | D13: 0 | E13: 0 | F13: =ROUND(E13*D13,0) -> 0 | K13: =IFERROR(#REF!/E13,0) -> 0
B14: 6.The quoted rates includes seggregating of good quality excavated earth from the clay / silty soil and storing in designted area for further treatment within the site premises for future landscape purposes including preserving top 300 mm layer of existing soil to meet MOEF requirements.. No extra is payable towards double handling. | D14: 0 | E14: 0 | F14: =ROUND(E14*D14,0) -> 0 | K14: =IFERROR(#REF!/E14,0) -> 0
B15: 7. Quoted rates shall incldue the preparation of temporary access road / Pathways, cross over, foot path, tracks, hard standings, temporary ramp to approach the excavated level etc, and temporary drains, rerouting of existing roads, supporting systems for existing MEP services if any and re-routing if required, etc. complete. at no extra cost. | D15: 0 | E15: 0 | F15: =ROUND(E15*D15,0) -> 0 | K15: =IFERROR(#REF!/E15,0) -> 0
B16: 8. Carting away all types of excavated earth outside or within the site shall be included and environmental norms to be followed for discarding excavated material with submission of document of proof. | D16: 0 | E16: 0 | F16: =ROUND(E16*D16,0) -> 0 | K16: =IFERROR(#REF!/E16,0) -> 0
B17: 9. Soil shall be classified as three types for billing purpose. | D17: 0 | E17: 0 | F17: =ROUND(E17*D17,0) -> 0 | K17: =IFERROR(#REF!/E17,0) -> 0
B18: a.Classification under hard rock excavation item which requires chiselling with compressed air/mechanical equipment's,controlled blasting, chemical splitting, diamond cutting etc. with necessary mechanical equipment's and loose boulders which requires splitting and handling. | D18: 0 | E18: 0 | F18: =ROUND(E18*D18,0) -> 0 | K18: =IFERROR(#REF!/E18,0) -> 0
B19: b. Classification under soft/medium/ weathered rock excavation item which is non poclainable, can be excavated using rock breaker attachments to JCB/Poclain, manual chiselling, etc. and loose boulders removal without spliting etc. | D19: 0 | E19: 0 | F19: =ROUND(E19*D19,0) -> 0 | K19: =IFERROR(#REF!/E19,0) -> 0
B20: c. Classification under soil excavation which is poclainable, can be excavated using JCB/Poclain etc. | D20: 0 | E20: 0 | F20: =ROUND(E20*D20,0) -> 0 | K20: =IFERROR(#REF!/E20,0) -> 0
B21: 10. Please note that the water and power required for construction shall be arranged by contractor and shall be included in the rates quoted. Necessary bore wells , bringing water from tankers from outside, DG, temporary power, power distribution lines etc are all part of the rates quoted. | D21: 0 | E21: 0 | F21: =ROUND(E21*D21,0) -> 0 | K21: =IFERROR(#REF!/E21,0) -> 0
B22: 11. The method statement shall include all safety features and protection to workmen, third party as well as property and services nearby. Methods of shoring and strutting should be fully detailed in the method statement. Removal of excavated material from excavated area, method of handling, method of storage (including any handling if necessary) as well as disposal shall be explained fully. Where controlled blasting is restricted, the contractor should ensure that all necessary statutory approvals are obtained in advance and kept in current and all necessary insurance and other covers shall be taken and kept valid in the case of sub-contracting this job, such cover shall include sub-contractor's workman also. Where controlled blasting is resorted to, contractor should take all necessary precaution for ensuring safety of life end property in the vicinity. | D22: 0 | E22: 0 | F22: =ROUND(E22*D22,0) -> 0 | K22: =IFERROR(#REF!/E22,0) -> 0
... B25: 14. Qty. shall be arrived at after taking block levels taken prior to and after excavation. The below mentioned quantities are based on soil report and the quantities may vary as per site condition. Quantity mentioned is tentative and may vary to any extent depending upon underlying ground profile to be exposed during excavation. | D25: 0 | E25: 0 | F25: =ROUND(E25*D25,0) -> 0 | K25: =IFERROR(#REF!/E25,0) -> 0
A26: 1.01 | B26: INDIVIDUAL FOOTING / POCKET EXCAVATION | D26: 0 | E26: 0 | F26: =ROUND(E26*D26,0) -> 0 | K26: =IFERROR(#REF!/E26,0) -> 0
B27: Excavation in all types of soil including dense soil, laterite reddish brown/Laterite reddish brown with patches/ dense soil disintegrated/ weathered/ soft rock (Poclainable) for Footings / RAFT of columns, trenches for drains, etc., by mechanical means including manual excavation for levelling, dressing the edges, with all leads and lifts. Dewatering of both ground and surface water, removal of slurry generated while excavation and keeping the area free of water with necessary shoring, strutting, required for keeping earth in position etc, Note: PCC area shall be considered for measurement (Working space & provision of slopes if required for execution shall not be paid separately). | C27: Cum | D27: 225 | E27: 4715 | F27: =ROUND(E27*D27,0) -> 1060875 | G27: 0 | H27: =G27*$D27 -> 0 | I27: =G27+E27 -> 4715 | J27: =I27*D27 -> 1060875 | K27: =IFERROR(#REF!/E27,0) -> 0
A28: 1.02 | B28: Specification & scope of work same as 1.01 but for Excavation in Hard rock / boulders (more than 1/2 Cum in size -Un poclainable) by chiselling/ wedging to required level for Raft, Footings of columns, Retaining walls, Core walls, catch pits, Lift pits,STP,UG tanks, trenches for drains, etc. to the required depth including all leads and lifts, dressing, grading, cleaning, excavating loose pockets directed and disposing etc. as per detailed specification and conforming to safety rules of Authority during the progress of work. Note: The percentage of voids to be deducted from stack measurement is 40% for hardrock or Initial levels will be taken before blasting hard rock and final levels will be taken after achieving required levels in presence of PIC. Note: PCC area shall be considered for measurement (Working space & provision of slopes if required for execution shall not be paid separately. Mode of measurement shall be by joint measurements/ levels before and after excavation). | C28: Cum | D28: 1926 | E28: 200 | F28: =ROUND(E28*D28,0) -> 385200 | G28: 0 | H28: =G28*$D28 -> 0 | I28: =G28+E28 -> 200 | J28: =I28*D28 -> 385200 | K28: =IFERROR(#REF!/E28,0) -> 0
A29: 1.03 | B29: BACKFILLING | D29: 0 | E29: 0 | F29: =ROUND(E29*D29,0) -> 0 | G29: 0 | H29: =G29*$D29 -> 0 | I29: =G29+E29 -> 0 | J29: =I29*D29 -> 0 | K29: =IFERROR(#REF!/E29,0) -> 0
B30: Supply and filling in foundations and the area whereever specified with approved good quality filling materials in plinths, area development etc. wherever specified in layers of not exceeding 150 mm thick including breaking clods,storing,transportation, double handling, watering, compacting each layer with vibratory compactor and at unaccessible places with wooden/steel rammers to achieve 90 to 95% proctor density at optimum moisture content, all leads and lifts, bailing/ pumping out of water to keep site dry while backfilling; cost shall include conveyance of all materials, labour, machinery etc. complete as directed.The rate to includes loading,unloading, hire and fuel charges for tools and plants and other incidental charges etc., complete. Cost to include all necessary royalty and other permission charges required to execute the works. | D30: 0 | E30: 0 | F30: =ROUND(E30*D30,0) -> 0 | G30: 0 | H30: =G30*$D30 -> 0 | I30: =G30+E30 -> 0 | J30: =I30*D30 -> 0 | K30: =IFERROR(#REF!/E30,0) -> 0
A31: i | B31: With excavated earth available at site | C31: Cum | D31: 160 | E31: 19376.99 | F31: =ROUND(E31*D31,0) -> 3100318 | G31: 0 | H31: =G31*$D31 -> 0 | I31: =G31+E31 -> 19376.99 | J31: =I31*D31 -> 3100318.4 | K31: =IFERROR(#REF!/E31,0) -> 0
A32: ii | B32: With Brought outside earth | C32: Cum | D32: 463 | E32: 21745.81 | F32: =ROUND(E32*D32,0) -> 10068310 | G32: 0 | H32: =G32*$D32 -> 0 | I32: =G32+E32 -> 21745.81 | J32: =I32*D32 -> 10068310 | L32: =17000*#REF! -> #REF! | M32: =#REF!-L32 -> #REF!
A33: 1.04 | B33: Carting away surplus earth/excavated material/debris/rock and like materials outside the plot and disposing off the same to the designated areas identified by the local authorities / project managers for dumping of such material, including spreading, compacting etc.,as per the norms by the local authorities. Mode of measurement- where measurement is not possible by level. i) Soil - truck measurement less 20% for voids. ii) Hard Rock - truck measurement less 50% for voids iii) Debris - truck measurement less 30% for voids. | C33: Cum | D33: 304 | E33: 200 | F33: =ROUND(E33*D33,0) -> 60800 | G33: 0 | H33: =G33*$D33 -> 0 | I33: =G33+E33 -> 200 | J33: =I33*D33 -> 60800 | K33: =IFERROR(#REF!/E33,0) -> 0
B34: Sub-Total | E34: 0 | F34: =SUM(F12:F33) -> 14675503 | G34: 0 | H34: =SUM(H12:H33) -> 0 | I34: =G34+E34 -> 0 | J34: =SUM(J12:J33) -> 14675503 | K34: =IFERROR(#REF!/E34,0) -> 0
A35: 1.1 | B35: ANTI-TERMITE TREATMENT WORKS | D35: 0 | E35: 0 | F35: =ROUND(E35*D35,0) -> 0 | G35: 0 | J35: =I35*D35 -> 0 | K35: =J35*E35 -> 0
A36: i | B36: Providing Pre-constructional anti- termite treatment and creating a chemical barrier to the building by injecting chemical emulsion of required concentrations under grade slab and Grade beam, around the Plinth, Plinth filling, trenches, junction of wall and floor, Retaining / side walls of basement floor, external perimeter of building, surrounding of pipes, expansion joints, below UG sump and etc.as per instructions of chemical manufacturer and all as directed. The treatment shall be carried out strictly in accordance with the technical specification and conforming to IS 6313 or equivalent BS specification. The chemical to be used as insecticides for the treatment shall be 50% EC (Imidacloprid 30.5 SC)and the application shall be dilute one part of chemical 50% EC with 49 parts of water to get 1% emulsion and strictly in accordance with the manufacturer's specification. Note : Measurement taken along external periphery of the building. Treatment shall extend to a width of 1m around the building. (Including 10 years warranty). | C36: Sqm | D36: 63 | E36: 22726.42 | F36: =ROUND(E36*D36,0) -> 1431764 | G36: 0 | H36: =G36*$D36 -> 0 | I36: =G36+E36 -> 22726.42 | J36: =I36*D36 -> 1431764.5 | K36: =IFERROR(#REF!/E36,0) -> 0
D37: 0 | F37: =ROUND(E37*D37,0) -> 0 | G37: 0 | I37: =G37+E37 -> 0 | K37: =IFERROR(#REF!/E37,0) -> 0
B38: Sub-Total | F38: =SUM(F36:F37) -> 1431764 | G38: 0 | H38: =SUM(H36:H37) -> 0 | I38: =G38+E38 -> 0 | J38: =SUM(J36:J37) -> 1431764.5 | K38: =IFERROR(#REF!/E38,0) -> 0
A39: 2 | B39: PLAIN CEMENT CONCRETE WORKS | D39: 0 | F39: =ROUND(E39*D39,0) -> 0 | G39: 0 | K39: =IFERROR(#REF!/E39,0) -> 0
B40: Unless otherwise specified rates quoted for all PCC works shall include the following : | D40: 0 | F40: =ROUND(E40*D40,0) -> 0 | G40: 0 | I40: =G40+E40 -> 0 | K40: =IFERROR(#REF!/E40,0) -> 0
B41: Cost of all materials, labour, equipment / tools & plants required, lead and lifts, conveyance, infrastructure facilities required etc. | D41: 0 | F41: =ROUND(E41*D41,0) -> 0 | G41: 0 | I41: =G41+E41 -> 0 | K41: =IFERROR(#REF!/E41,0) -> 0
B42: The contractors are particularly advised to study the relevant drawings carefully before quoting. | D42: 0 | F42: =ROUND(E42*D42,0) -> 0 | G42: 0 | I42: =G42+E42 -> 0 | K42: =IFERROR(#REF!/E42,0) -> 0
B43: Minimum cementitious content for concrete shall be as per cement constants specified in the technical specification. | D43: 0 | F43: =ROUND(E43*D43,0) -> 0 | G43: 0 | I43: =G43+E43 -> 0 | K43: =IFERROR(#REF!/E43,0) -> 0
...

Sheet Derived Items
A1: PROJECT - PROVIDENT BOTANICO
B2: DERIVED ITEMS - 1
A3: Item No. | B3: Description of works | C3: UOM | D3: Qty | E3: Rate | F3: Amount (Rs.) | G3: Remarks
A4: A | B4: Derived Items
A5: 1 | B5: REINFORCED CEMENT CONCRETE
B6: Providing & laying plant mixed design mix reinforced cement concrete conforming to grades as specified in (IS 456 - 2000) and as per specifications mentioned below at all levels using 20mm & down size aggregates, fine aggregates, OPC, necessary admixtures approved by Consultants (Conplast SP 430SRV from Fosroc or equivalent), including designing the mix, trial cubes, accelerated curing, weigh batching, mechanical mixing, transporting, pumping and placing at all levels, excluding the cost of steel reinforcement, centring, shuttering but inclusive of cost towards pumping using line pump or boom placer, scaffolding, compacting with vibrators, construction joint treatments, curing and hacking the exposed surfaces wherever required to receive plaster or floated steel trowelled surface whenever specified. The rate shall include cost of arrangements to provide recesses to slabs, columns, walls and placing and securing properly within the formwork sleeves and / or opening in slabs, construction joints, laying to required shape, size and slope all as per drawings. The mix proportion of cement with that of GGBS shall be confirming to latest IS standards.
B7: The rate shall include providing and fixing the required PVC sleeves up to 200 mm dia pockets and opening etc., cleaning the site debris stacking the material, hoisting equipment's, shutter accessories and fixing pipe / plates / inserts in perfect size level , plumb etc. as directed by Engineer In Charge and as per technical specifications in the tender. Repairing / replacing the formwork, filling all the holes created due to shuttering / sleeves provided for passage of plumbing, FF pipes / Electrical cables with approved non shrink filler material etc. complete to the satisfaction of Client / the Engineer. Hacking of RCC faces as specified and directed by Engineer In Charge to be included in quoted rate of RCC.
B8: Cost to include appropriate dewatering wherever necessary, cost of all materials, labours, all lead and lifts, tools, plant and machinery, hire and fuel charges and all other incidental charges etc., all as per specifications, drawings and as directed.
A9: 1.1-A-i | B9: Columns & shear Walls at all levels
B10: M35 grade
A11: a | B11: Stilt floor | C11: Cum | D11: 256.98 | E11: 7309 | F11: =$D11*E11 -> 1878266.8
A12: b | B12: 1st floor | C12: Cum | D12: 116.03 | E12: 7309 | F12: =$D12*E12 -> 848063.27
A13: c | B13: 2nd floor | C13: Cum | D13: 99.22 | E13: 7309 | F13: =$D13*E13 -> 725198.98
A14: d | B14: 3rd floor | C14: Cum | D14: 86.5 | E14: 7309 | F14: =$D14*E14 -> 632228.5
A15: 1.1-A-ii | B15: M50 Grade
A16: a | B16: Stilt floor | C16: Cum | D16: 63.84 | E16: 8532 | F16: =$D16*E16 -> 544682.88
A17: 1.1-A-iii | B17: M40 Grade
A18: a | B18: 1st floor | C18: Cum | D18: 63.84 | E18: 7682 | F18: =$D18*E18 -> 490418.88
A19: b | B19: 2nd floor | C19: Cum | D19: 63.84 | E19: 7682 | F19: =$D19*E19 -> 490418.88
A20: c | B20: 3rd floor | C20: Cum | D20: 80.28 | E20: 7682 | F20: =$D20*E20 -> 616710.96
A21: 1.1-B-i | B21: Core Walls and Staircase walls
B22: M50 Grade
A23: a | B23: Stilt floor | C23: Cum | D23: 6.36 | E23: 8532 | F23: =$D23*E23 -> 54263.52
A24: 1.1-B-ii | B24: M40 Grade | D24: 0 | F24: =$D24*E24 -> 0
A25: a | B25: 1st floor | C25: Cum | D25: 6.36 | E25: 7682 | F25: =$D25*E25 -> 48857.52
A26: b | B26: 2nd floor | C26: Cum | D26: 6.36 | E26: 7682 | F26: =$D26*E26 -> 48857.52
A27: c | B27: 3rd floor | C27: Cum | D27: 6.15 | E27: 7682 | F27: =$D27*E27 -> 47244.3
A28: 1.1-C | B28: M40 grade-Regular Slab | D28: 0 | F28: =$D28*E28 -> 0
A29: a | B29: 6th floor (Club house terrace) | C29: Cum | D29: 99.79 | E29: 7682 | F29: =$D29*E29 -> 766586.78
A30: 1.1-D | B30: M40 grade-Beams | D30: 0 | F30: =$D30*E30 -> 0
A31: a | B31: 6th floor (Club house terrace) | C31: Cum | D31: 124.84 | E31: 7682 | F31: =$D31*E31 -> 959020.88
A32: 1.2 | B32: SDC / Free flow concrete for below mentioned elements | D32: 0 | E32: 0 | F32: =$D32*E32 -> 0
B33: Providing, placing and compacting Smart Dynamic Cement Concrete / Free flow concrete, High flow concrete, non-segregate, free flow conforming to specified grade (IS 456-2000) the RMC of various grades with 20 mm and down graded aggregate of granite basalt or trap, in positions at all levels and heights, in all required shapes / profiles / inclinations for all reinforced concrete members such as RCC walls, columns, Shear walls, Core walls, and other miscellaneous members and all architectural features as per specifications / IS codes, including designing the mix, trial cubes, accelerated curing, weigh batching, mechanical mixing, transporting, pumping and placing at all levels, inclusive of cost towards pumping using line pump or boom placer, scaffolding, compacting with vibrators, construction joint treatments, curing and hacking the exposed surfaces wherever required to receive plaster or floated steel trowelled surface whenever specified. The rate shall include cost of arrangements to provide recesses to slabs, columns, walls and placing and securing properly within the formwork sleeves and / or opening in slabs, construction joints, laying to required shape, size and slope all as per drawings and as directed by the Engineer In Charge.
B34: The rate shall also include the cost of necessary labour, plant and machineries, dewatering, curing the concrete as directed by the Engineer In Charge. curing pipes / Hessain cloth, tools and tackles, making the surface good to receive the finishes, Cover blocks of PVC of approved make / quality (in case of concrete cover blocks, One grade higher Ready made / Factory made to be used as against the relevant structural member grade), making provision of stand - by vibrators and needles , buttering with cement slurry , removing laitance from surface , protecting the newly placed concrete from rain / heat with PVC sheets , marking the date of concreting, filling the required checklist / pour card, making necessary arrangements for ponding, curing, clearing the area of debris, providing required labour, pumping and hoisting by any mechanical means etc. complete as directed and to the satisfaction of the Client / the Engineer as per the technical specification of the tender.
B35: The rate shall include providing and fixing the required PVC sleeves up to 200 mm dia pockets and opening etc., cleaning the site debris stacking the material, hoisting equipment's, shutter accessories and fixing pipe / plates / inserts in perfect size level, plumb etc. as directed by Client / the Engineer and as per technical specifications in the tender. Repairing / replacing the formwork, filling all the holes created due to shuttering / sleeves provided for passage of plumbing, FF pipes / Electrical cables with approved non shrink filler material etc. complete to the satisfaction of Client / the Engineer. Hacking of RCC faces as specified and directed by Client / the Engineer to be included in quoted rate of RCC.
B36: The rates shall include the cost of necessary admixtures approved by consultant to get required workability & strength (Glenium series or equivalent) with flow dia of approximately 600 mm and sufficient retention in workability to avoid cold joints. use ordinary Portland cement of grade 53 from approved manufacturer & GGBS of approved brand in proportions of supplementary cementations materials as per Indian Standards. and follow the provident Standard Work Procedures for approval, Mix design, execution and quality measures.
A37: 1.2.1 | B37: Columns and shear walls at all levels | D37: 0 | E37: 0 | F37: =$D37*E37 -> 0
B38: M50 grade | D38: 0 | E38: 0 | F38: =$D38*E38 -> 0
A39: a | B39: 1st floor | C39: Cum | D39: 153.85 | E39: 8847 | F39: =$D39*E39 -> 1361110.9
B40: M30 grade | D40: 0 | E40: 0 | F40: =$D40*E40 -> 0
...

Sheet NT#01
A1: PROJECT - PROVIDENT BOTANICO
B2: NON TENDERED ITEMS - 1
A3: Item No. | B3: Description of works | C3: UOM | D3: Qty | E3: Rate | F3: Amount (Rs.) | G3: Remarks
A4: 1 | B4: Supplying, installing, testing and commissioning of RCC Hume Pipe 200mm Dia NP3/68101190 laid to the required level and grade with SS TYPE COLLAR joining in CM 1:3 making necessary connections as required etc., complete. (Provision for road crossings) | C4: Rmt | D4: 80 | E4: 836 | F4: =$D4*E4 -> 66880
A5: 2 | B5: Supplying, installing, testing and commissioning of Rcc Hume Pipe 300Mm Dia NP3/68101190 laid to the required level and grade with SS TYPE COLLAR joining in CM 1:3 making necessary connections as required etc., complete. (Provision for road crossings) | C5: Rmt | D5: 80 | E5: 1221 | F5: =$D5*E5 -> 97680
A6: 3 | B6: Supplying, installing, testing and commissioning of Rcc Hume Pipe 450Mm Dia NP3/68101190 laid to the required level and grade with SS TYPE COLLAR joining in CM 1:3 making necessary connections as required etc., complete. (Provision for road crossings) | C6: Rmt | D6: 115 | E6: 2302 | F6: =$D6*E6 -> 264730
A7: 4 | B7: Providing, supplying, placing and fixing in position to create gap for expansion joints of specified thick using 25mm tk of lower density of supreme make - CAPCELL HD100 of 100 kg/cum density during execution of concrete elements at all expansion joints and separation joints at all levels and wherever specified to the required sizes, shapes, etc., complete. The rate is including all kind of wastages, lead and Lifts etc. | C7: Sqm | D7: 440.92 | E7: 1069 | F7: =$D7*E7 -> 471343.48
A8: 5 | B8: Additional threading maked at column termination place. Providing and fixing Mechanical Splicing using threaded coupler to the reinforcement bars of specified dia and grade using high yield strength standard couplers of specially produced steel to join ribbed bearing bars machine cut end to end. Cost to include necessary supply of threaded couplers of various diameters, reducing diameters,transportation,coupling at site by mechanical means, threading of reinforcement bars at ends,erection at site, testing of random samples, testing of joints at site using ultrasonic methods required by Structural consultant at intervals as directed, protection of threaded ends using PVC covers, all tools and tackels, lead and lift etc., complete at all levels and location specified as per drawings.Cost to include necessary testing of couplers as per IS 16172 | F8: =$D8*E8 -> 0
A9: a | B9: CRE- MS Couplers - 32mm dia | C9: Nos | D9: 112 | E9: 39.1 | F9: =$D9*E9 -> 4379.2
A10: b | B10: CRE- MS Couplers - 25mm dia | C10: Nos | D10: 250 | E10: 32.2 | F10: =$D10*E10 -> 8050
A11: c | B11: CRE- MS Couplers - 20mm dia | C11: Nos | D11: 184 | E11: 29.9 | F11: =$D11*E11 -> 5501.6
A12: d | B12: CRE- MS Couplers - 16mm dia | C12: Nos | D12: 1962 | E12: 27.6 | F12: =$D12*E12 -> 54151.2
A13: e | B13: CRE- Reducer Couplers - 32 to 20 mm dia | C13: Nos | D13: 4 | E13: 39.1 | F13: =$D13*E13 -> 156.4
A14: f | B14: CRE- Reducer Couplers - 25 to 20 mm dia | C14: Nos | D14: 14 | E14: 32.2 | F14: =$D14*E14 -> 450.8
A15: 6 | B15: STP Hard rock excavation (Grid-(ML-M to ML-P) Specification & scope of work same as 1.01 of the BOQ but for Excavation in Hard rock / boulders (more than 1/2 Cum in size -Un poclainable) by chiselling/ wedging to required level for Raft, Footings of columns, Retaining walls, Core walls, catch pits, Lift pits,STP,UG tanks, trenches for drains, etc. to the required depth including all leads and lifts, dressing, grading, cleaning, excavating loose pockets directed and disposing etc. as per detailed specification and conforming to safety rules of Authority during the progress of work. Note: The percentage of voids to be deducted from stack measurement is 40% for hardrock or Initial levels will be taken before blasting hard rock and final levels will be taken after achieving required levels in presence of PIC. | C15: Days | D15: 11 | E15: 18464.09 | F15: =$D15*E15 -> 203104.99
A16: 7 | B16: Lift WALLS WATERPROOFING WORKS- (EXTERNAL) - Lift Walls - External walls (Extra over and above rate of item no-7.2-I of the BOQ for Lift External Wall Waterproofing Works) | F16: =$D16*E16 -> 0
B17: 1. Surface preparation: Before starting of waterproofing works the surface of the wall should be made free of any loose particles, vegetation, grease or oily matters etc. All tie rod holes should be filled properly. All honeycombs should be repaired as per approved repair procedures. Treating the Construction Joints : Chase opening the Construction Joints by providing ''V " groove, removing the dust and clean the designated area following by providing with approved nonshrink high strength cemenitious grout, finishing, curing etc. as per manufacturers specification and as directed. Any damp spots on the walls should be attended by grouting cement mixed with flow enhancers like Cebex-100 or equivalent until the leak or dampness is fully arrested. When PVC pipes are inserted in the designated openings in the slab, it should be applied with epoxy bonding agent sprayed with sand on the portion coming in contact with non shrink grout or mortar or concrete to enhance the bonding and packed with non shrink grout includiing scafolding as directed. All sharp edges and corners to be chamferred / haunched to receive the membrane. 2. Providing and laying minimum 1.5 mm thick self adhesive, self healing type SBS based membranes minimum puncture resistance of 220N(ASTM E154), tensile resistance over 200%, Elongation over 200%(ASTM D-412) and tear resistance of more than 200N (ASTM D1004). The membrane shall be laid over a compatible primer as per Manufacturer's specification with sufficient overlaps. 3. This membrane should be protected with 250 GSM minimum non woven polyester mat for high puncture resistance laid over the membrane either loosely laid or fixed as per manufacturer specifications. 4. The SBS membrane as well as the protection layer should have sufficient overlap as per manufacturer specifications. 5. The applicator/manufacturer should submit the details of waterproofing near the penetrations on the wall. 6. The membrane should be terminated on all sides properly with watertight joints. | F17: =$D17*E17 -> 0
B18: 7.The manufacturer/applicator should submit the details and get client approval prior to start the work. 8.The contractor to include cost of termination of waterproofing system with necessary overlapping, joint treatment etc complete all as per manufacturer's recommendations. 9.Treatment shall be provided from standard manufacturers like BASF, SIKA, FOSROC or equivalent. Lift Walls - External walls (Extra over and above rate of item no-7.2-i (BOQ) | C18: Sqm | D18: 615 | E18: 370 | F18: =$D18*E18 -> 227550
A19: 8 | B19: Dewatering in Construction site various locations (Drain water & Underground water uplift in the construction site) | C19: Hr | D19: 384.7 | E19: 254 | F19: =$D19*E19 -> 97713.8
A20: 9 | B20: Balcony Shaft Louvers - UPVC Wind Pressure consideration:1.5Kpa (including factor of safety), fastners shall be of Hilti or fischer make, Water & Smoke test to be done, Glass shall come with Protection film which shall be removed during handing over. Actual Measurement to be taken at site for Windows/Doors opening. Providing and fixing of UPVC Openable louvers with single door made out of approved 5mm thick UPVC sections, make and colour as approved by the architects with louvers fixed to the frame all as per details in the drawings and manufacturer specifications, completely waterproof and free from rattling and all standard accessories like locks, handles, hinges, screws, nails, hardware of approved make, all consumables etc., water tight joints should be ensured with the masonary/RCC by using sealants as & whereever necessary. Item inclusive of all fabrication, transportation,fixing at site inclusive of all scaffolding etc., complete to suit the overall sizes of openings as detailed in drawing and as directed by the Architect / Engineer-in-charge. Refer the drawings for pricing etc. Location: Balcony Shaft (DD1) - Size : 750mm x 1300mm | C20: Sqm | D20: 2036 | E20: =ROUND(3125+(3125*5%),2) -> 3281.25 | F20: =$D20*E20 -> 6680625
A21: Total Amount (Excl GST) | F21: =SUM(F4:F20) -> 8182316.5

Sheet RFA
A3: Sl No | B3: Description | C3: Amount (Rs.) Excl GST
C4: Previous Wo | D4: Current | G4: Revised WO
D5: Qty Variation | E5: NT Items | F5: Gross VO
A6: 1 | B6: Initial Contract | C6: ='Grand summary '!C38 -> 3.3329889e+09 | D6: 0 | E6: 0 | F6: 0 | G6: =C6 -> 3.3329889e+09 | J6: Sl.No | K6: Description | L6: Amount (Rs) | M6: Remarks
A7: 2 | B7: VO#01 | C7: =G6 -> 3.3329889e+09 | F7: =D7+E7 -> 0 | G7: =C7 -> 3.3329889e+09 | J7: 1 | K7: Value of Work Order | L7: =C7 -> 3.3329889e+09
A8: 3 | B8: Present VO#02 | C8: =G7 -> 3.3329889e+09 | D8: ='Part-A & B_BOQ '!H2653 -> -2351580 | E8: ='NT#01'!F21 -> 8182316.5 | F8: =D8+E8 -> 5830736.5 | G8: =F8+C8 -> 3.3388197e+09 | J8: 2 | K8: Value of VO#01 | L8: =F7 -> 0 | M8: Additional Scope for Compound Wall & Sub Soil Drainage System
K9: Revised contract value | L9: =SUM(L7:L8) -> 3.3329889e+09

Sheet M35 Grade Rate Calculation 
C4: S.No | D4: Description | G4: Rate
C5: 1 | D5: For M35 Grade Rate Calculation
C6: 2 | D6: M30 Grade BOQ Rate | G6: 7109 | H6: CUM | J6: =#REF! -> #REF!
C7: 3 | D7: M35 Grade Cement Co-efficient Difference
C8: 4 | D8: M30 Grade Cementitious Content | E8: 360 | F8: Kg/Cum
C9: 5 | D9: M35 Grade Cementitious Content | E9: 400 | F9: Kg/Cum
C10: 6 | D10: Difference in Cementitious Content | E10: =E9-E8 -> 40 | F10: Kg/Cum
C11: 7 | D11: cement Basic Rate | E11: 250 | F11: Per Bag
C12: 8 | D12: For M35 Grade Cementitious difference Amount (40/50*250) | G12: =(40/50*250) -> 200
D13: M35 Grate Rate | G13: =SUM(G5:G12) -> 7309 | H13: CUM
