Workbook
Name _____________IV65675: '[1]2-Conc'!#REF!
Name ____________IV65675: '[1]2-Conc'!#REF!
Name ___________IV65675: '[1]2-Conc'!#REF!
Name __________IV65675: #REF!
Name _________IV65675: '[1]2-Conc'!#REF!
Name _______IV65675: '[1]2-Conc'!#REF!
Name ______IV65675: #REF!
Name _____IV65675: '[1]2-Conc'!#REF!
Name ____IV65675: '[1]2-Conc'!#REF!
Name ___IV65675: '[1]2-Conc'!#REF!
Name __IV65675: '[1]2-Conc'!#REF!
Name _boq1: [2]BOQ!#REF!
Name _IV65675: '[1]2-Conc'!#REF!
Name A: #REF!
Name aa: #REF!
Name aaa: #REF!
Name b: #REF!
Name beam: [3]Lstsub!#REF!
Name Beamupper: [2]BOQ!#REF!
Name boqformat: [4]BOQ!#REF!
Name CA: [3]Lstsub!#REF!
Name Excluded: [4]BOQ!#REF!
Name FH: '[5]2-Conc'!#REF!
Name gd: [3]Lstsub!#REF!
Name GFJHN: '[1]2-Conc'!#REF!
Name H: #REF!
Name Included: [4]BOQ!#REF!
Name jh: #REF!
Name jhiuyhip: #REF!
Name kFOB: '[6]CIF COST ITEM'!#REF!
Name kIF: '[6]CIF COST ITEM'!#REF!
Name KK: #REF!
Name kloc: '[6]CIF COST ITEM'!#REF!
Name mez: [4]BOQ!#REF!
Name nw: [3]Lstsub!#REF!
Name OO: #REF!
Name QR.: [4]BOQ!#REF!
Name RA: [3]Lstsub!#REF!
Name RAPS: [3]Lstsub!#REF!
Name RCD: [3]Lstsub!#REF!
Name RCS: [3]Lstsub!#REF!
Name rgt: '[1]2-Conc'!#REF!
Name RL: [3]Lstsub!#REF!
Name RLPS: [3]Lstsub!#REF!
Name SS: '[7]2-Conc'!#REF!
Name SSS: #REF!
Name TSD: [3]Lstsub!#REF!
Name TSS: [3]Lstsub!#REF!
Name tyfy: #REF!
Name xxxx: [3]Lstsub!#REF!

Sheet Grand summary
B2: PROPOSED RESIDENTIAL DEVELOPMENT PROVIDENT ECOPOLITAN, BENGALURU
B3: INSTRUCTIONS TO TENDER
B4: 1 | C4: The Schedule of Rate shall be read with all the other sections of this bidding document including technical specification, general and special conditions of contract, safety requirements, EHS norms etc.
B5: 2 | C5: All the works shall be measured upon completion and paid for at the rate quoted and accepted in the “Schedule of Price”. In case any activity though specifically not covered in schedule of rates descriptions but the same is covered under scope of work/scope of supply/specification drawings etc. no extra claim on this account shall be entertained, since schedule of price is to be read in conjunction with all other documents forming part of the contract.
B6: 3 | C6: Written approval for the aggregates, materials used for construction to be obtained from the client /the Engineer prior to commencement of work.
B7: 4 | C7: All items of work mentioned in the Schedule of Rates shall be carried out as per the specifications, drawings and instructions of Client/the Engineer and the rates are deemed to be inclusive of material, consumable, labour, supervision, testing, tools and tackles and detailing of construction/fabrication drawings, wherever required as called for in the detail specification and conditions of the Contract.
B8: 5 | C8: This is an item rate tender and quantities are tentative. The Contractor's unit rates quoted shall not change for any variation in quantities.
B9: 6 | C9: Suitable barricading, warning systems, signages, sand cushing. Multiple handling of materials shall be taken into account in view of restricted area availabe for contruction. Extra claim for cost and time will not be accepted on account of failure to take into account the above factors prior to quoting.
B10: 7 | C10: Tests on materials shall confirm to IS Specification and the test shall be carried out as directed either at site Laboratory or at any approved test laboratory.
B11: 8 | C11: Material shall be of good, approved, acceptable quality & purchased from approved source; got approved from the Engineer prior to usage and meeting all relevant codal norms.
B12: 9 | C12: Work shall be carried out as per latest good for construction drawings, specifications & carried out to the satisfaction of the engineer.
B13: 10 | C13: Work will be measured and paid only as shown on the drawing as per applicable clause in IS 1200 unless or otherwise specified elsewhere.
B15: SUMMARY
B16: Sl.No. | C16: Description | D16: Amount (Rs.) (Incl Course Putty)
D17: Ph - 1 | E17: Ph 2 | F17: Total
B18: A | C18: CIVIL & STRUCTURAL WORKS
B20: 1 | C20: Earthwork & Antitermite Works | D20: ='Part-A & B_BOQ'!H33+'Part-A & B_BOQ'!H37 -> 4906025.7 | E20: ='Part-A & B_BOQ'!I33+'Part-A & B_BOQ'!I37 -> 943346.34 | F20: =SUM(D20:E20) -> 5849372
B21: =B20+1 -> 2 | C21: Plain cement concrete works | D21: ='Part-A & B_BOQ'!H58 -> 10582619 | E21: ='Part-A & B_BOQ'!I58 -> 2536822.6 | F21: =SUM(D21:E21) -> 13119442
B22: =B21+1 -> 3 | C22: Reinforced cement concrete works | D22: ='Part-A & B_BOQ'!H332 -> 5.52034e+08 | E22: ='Part-A & B_BOQ'!I332 -> 1.4781665e+08 | F22: =SUM(D22:E22) -> 6.9985065e+08
B23: =B22+1 -> 4 | C23: Form work | D23: ='Part-A & B_BOQ'!H463 -> 4.3673365e+08 | E23: ='Part-A & B_BOQ'!I463 -> 1.1260815e+08 | F23: =SUM(D23:E23) -> 5.493418e+08
B24: =B23+1 -> 5 | C24: Reinforcement Steel Works | D24: ='Part-A & B_BOQ'!H496 -> 5.921355e+08 | E24: ='Part-A & B_BOQ'!I496 -> 1.1638253e+08 | F24: =SUM(D24:E24) -> 7.0851803e+08
B25: =B24+1 -> 6 | C25: Concrete Flooring works | D25: ='Part-A & B_BOQ'!H548 -> 71378947 | E25: ='Part-A & B_BOQ'!I548 -> 10371681 | F25: =SUM(D25:E25) -> 81750628
B26: =B25+1 -> 7 | C26: Waterproofing works (through NSC) | D26: ='Part-A & B_BOQ'!H625 -> 80780574 | E26: ='Part-A & B_BOQ'!I625 -> 17186503 | F26: =SUM(D26:E26) -> 97967076
B27: =B26+1 -> 8 | C27: Expansion Joints (through NSC) | D27: ='Part-A & B_BOQ'!H671 -> 24090074 | E27: ='Part-A & B_BOQ'!I671 -> 1226506.8 | F27: =SUM(D27:E27) -> 25316581
B28: =B27+1 -> 9 | C28: Miscellaneous works | D28: ='Part-A & B_BOQ'!H750 -> 6149479.9 | E28: ='Part-A & B_BOQ'!I750 -> 782887.34 | F28: =SUM(D28:E28) -> 6932367.2
B29: =B28+1 -> 10 | C29: Conduit with accessories | D29: ='Part-A & B_BOQ'!H765 -> 6127294.2 | E29: ='Part-A & B_BOQ'!I765 -> 1372044.3 | F29: =SUM(D29:E29) -> 7499338.5
B30: =B29+1 -> 11 | C30: Masonry works | D30: ='Part-A & B_BOQ'!H827 -> 13659266 | E30: ='Part-A & B_BOQ'!I827 -> 1997022.4 | F30: =SUM(D30:E30) -> 15656289
B31: =B30+1 -> 12 | C31: Plastering works | D31: ='Part-A & B_BOQ'!H933 -> 39215475 | E31: ='Part-A & B_BOQ'!I933 -> 8563678 | F31: =SUM(D31:E31) -> 47779153
C32: Sub-Total | D32: =SUM(D19:D31) -> 1.8377929e+09 | E32: =SUM(E19:E31) -> 4.2178782e+08 | F32: =SUM(F19:F31) -> 2.2595807e+09
B34: B | C34: FINISHING WORKS
B36: 1 | C36: Gypsum Plastering works | D36: ='Part-A & B_BOQ'!H1001 -> 81720366 | E36: ='Part-A & B_BOQ'!I1001 -> 24225197 | F36: =SUM(D36:E36) -> 1.0594556e+08
B37: 2 | C37: Painting works | D37: ='Part-A & B_BOQ'!H1171 -> 1.2197576e+08 | E37: ='Part-A & B_BOQ'!I1171 -> 36679464 | F37: =SUM(D37:E37) -> 1.5865522e+08
B38: 3 | C38: Flooring, Dadoing, Skirting works | D38: ='Part-A & B_BOQ'!H1644 -> 2.333963e+08 | E38: ='Part-A & B_BOQ'!I1644 -> 78290369 | F38: =SUM(D38:E38) -> 3.1168667e+08
B39: 4 | C39: Structural Steel works | D39: ='Part-A & B_BOQ'!H1738 -> 29568146 | E39: ='Part-A & B_BOQ'!I1738 -> 6885942.7 | F39: =SUM(D39:E39) -> 36454089
B40: 5 | C40: Miscellaneous works | D40: ='Part-A & B_BOQ'!H1778 -> 48407816 | E40: ='Part-A & B_BOQ'!I1778 -> 9807160.4 | F40: =SUM(D40:E40) -> 58214976
B41: 6 | C41: Joinery works | D41: ='Part-A & B_BOQ'!H1954 -> 88350480 | E41: ='Part-A & B_BOQ'!I1954 -> 28616662 | F41: =SUM(D41:E41) -> 116967142
B42: 7 | C42: UPVC Works | D42: ='Part-A & B_BOQ'!H2389 -> 0 | E42: ='Part-A & B_BOQ'!I2389 -> 0 | F42: =SUM(D42:E42) -> 0
B43: 8 | C43: False ceiling works | D43: ='Part-A & B_BOQ'!H2418 -> 9848691.3 | E43: ='Part-A & B_BOQ'!I2418 -> 3134128.2 | F43: =SUM(D43:E43) -> 12982820
C44: Sub-Total | D44: =SUM(D36:D43) -> 6.1326756e+08 | E44: =SUM(E36:E43) -> 1.8763892e+08 | F44: =SUM(F36:F43) -> 8.0090648e+08
C46: Total Excluding Taxes | D46: =D32+D44 -> 2.4510605e+09 | E46: =E32+E44 -> 6.0942675e+08 | F46: =F32+F44 -> 3.0604872e+09
...

Sheet Summary_Final
A1: Project - Provident Ecopolitan, Aerospace Park, Bangalore.
A2: Summary - Structure & Finishing Works
A3: Sl.No. | B3: Description | C3: As per VO#02 | D3: As per Actual | E3: Present Variation | F3: Remarks
C5: Amount (Rs.)
A6: A | B6: CIVIL & STRUCTURAL WORKS
A7: 1 | B7: Earthwork & Antitermite Works | C7: ='Grand summary'!F20 -> 5849372 | D7: =E7-C7 -> 3595399.4 | E7: ='Part-A & B_BOQ'!O33+'Part-A & B_BOQ'!O37 -> 9444771.4 | J7: 21706453 | L7: =D7-J7 -> -18111054
A8: =A7+1 -> 2 | B8: Plain cement concrete works | C8: ='Grand summary'!F21 -> 13119442 | D8: =E8-C8 -> 6010316.7 | E8: ='Part-A & B_BOQ'!O58 -> 19129759 | J8: 28217815 | L8: =D8-J8 -> -22207498
A9: =A8+1 -> 3 | B9: Reinforced cement concrete works | C9: ='Grand summary'!F22 -> 6.9985065e+08 | D9: =E9-C9 -> -20811382 | E9: ='Part-A & B_BOQ'!O332 -> 6.7903927e+08 | J9: 6.4073192e+08 | L9: =D9-J9 -> -6.615433e+08
A10: =A9+1 -> 4 | B10: Form work | C10: ='Grand summary'!F23 -> 5.493418e+08 | D10: =E10-C10 -> 17278454 | E10: ='Part-A & B_BOQ'!O463 -> 5.6662026e+08 | J10: 5.2012134e+08 | L10: =D10-J10 -> -5.0284289e+08
A11: =A10+1 -> 5 | B11: Reinforcement Steel Works | C11: ='Grand summary'!F24 -> 7.0851803e+08 | D11: =E11-C11 -> -2340950.2 | E11: ='Part-A & B_BOQ'!O496 -> 7.0617708e+08 | J11: 729720015 | L11: =D11-J11 -> -7.3206097e+08
A12: =A11+1 -> 6 | B12: Concrete Flooring works | C12: ='Grand summary'!F25 -> 81750628 | D12: =E12-C12 -> -6695511.3 | E12: ='Part-A & B_BOQ'!O548 -> 75055117 | J12: 85598862 | L12: =D12-J12 -> -92294373
A13: =A12+1 -> 7 | B13: Waterproofing works | C13: ='Grand summary'!F26 -> 97967076 | D13: =E13-C13 -> 474215.11 | E13: ='Part-A & B_BOQ'!O625 -> 98441292 | J13: 122161309 | L13: =D13-J13 -> -1.2168709e+08
A14: =A13+1 -> 8 | B14: Expansion Joints | C14: ='Grand summary'!F27 -> 25316581 | D14: =E14-C14 -> 0 | E14: ='Part-A & B_BOQ'!O671 -> 25316581 | J14: 25833910 | L14: =D14-J14 -> -25833910
A15: =A14+1 -> 9 | B15: Miscellaneous works | C15: ='Grand summary'!F28 -> 6932367.2 | D15: =E15-C15 -> -2074452.3 | E15: ='Part-A & B_BOQ'!O750 -> 4857914.9 | J15: 8982055 | L15: =D15-J15 -> -11056507
A16: =A15+1 -> 10 | B16: Conduit with accessories | C16: ='Grand summary'!F29 -> 7499338.5 | D16: =E16-C16 -> -1150248.7 | E16: ='Part-A & B_BOQ'!O765 -> 6349089.8 | J16: 24362630 | L16: =D16-J16 -> -25512879
A17: =A16+1 -> 11 | B17: Masonry works | C17: ='Grand summary'!F30 -> 15656289 | D17: =E17-C17 -> -227732.82 | E17: ='Part-A & B_BOQ'!O827 -> 15428556 | J17: 19477735 | L17: =D17-J17 -> -19705468
A18: =A17+1 -> 12 | B18: Plastering works | C18: ='Grand summary'!F31 -> 47779153 | D18: =E18-C18 -> -244144.25 | E18: ='Part-A & B_BOQ'!O933 -> 47535009 | J18: 46436588 | L18: =D18-J18 -> -46680732
B19: Sub-Total - A | C19: =SUM(C7:C18) -> 2.2595807e+09 | D19: =SUM(D7:D18) -> -6186036 | E19: =SUM(E7:E18) -> 2.2533947e+09 | J19: =SUM(J7:J18) -> 2.2733506e+09 | L19: =SUM(L7:L18) -> -2.2795367e+09
A20: B | B20: FINISHING WORKS | L20: =D20-J20 -> 0
A21: 1 | B21: Gypsum Plastering works | C21: ='Grand summary'!F36 -> 1.0594556e+08 | D21: =E21-C21 -> -6040315.6 | E21: ='Part-A & B_BOQ'!O1001 -> 99905248 | J21: 80879463 | L21: =D21-J21 -> -86919779
A22: 2 | B22: Painting works | C22: ='Part-A & B_BOQ'!O1171 -> 1.5865522e+08 | D22: =E22-C22 -> 0 | E22: ='Part-A & B_BOQ'!O1171 -> 1.5865522e+08 | J22: 138465821 | L22: =D22-J22 -> -138465821
A23: 3 | B23: Flooring, Dadoing, Skirting works | C23: ='Part-A & B_BOQ'!J1644 -> 3.1168667e+08 | D23: =E23-C23 -> 3429530.8 | E23: ='Part-A & B_BOQ'!O1644 -> 3.151162e+08 | J23: 298669783 | L23: =D23-J23 -> -2.9524025e+08
A24: 4 | B24: Structural Steel works | C24: ='Grand summary'!F39 -> 36454089 | D24: =E24-C24 -> -4840100 | E24: ='Part-A & B_BOQ'!O1738 -> 31613989 | J24: 27158421 | L24: =D24-J24 -> -31998521
A25: 5 | B25: Miscellaneous works | C25: ='Grand summary'!F40 -> 58214976 | D25: =E25-C25 -> -21785979 | E25: ='Part-A & B_BOQ'!O1778 -> 36428998 | J25: 43257223 | L25: =D25-J25 -> -65043202
A26: 6 | B26: Joinery works | C26: ='Grand summary'!F41 -> 116967142 | D26: =E26-C26 -> 4261950 | E26: ='Part-A & B_BOQ'!O1954 -> 121229092 | J26: 128956950 | L26: =D26-J26 -> -124695000
A27: 7 | B27: UPVC Works | C27: ='Grand summary'!F42 -> 0 | D27: =E27-C27 -> 0 | E27: ='Part-A & B_BOQ'!O2389 -> 0 | J27: 106523340 | L27: =D27-J27 -> -106523340
A28: 8 | B28: False ceiling works | C28: ='Grand summary'!F43 -> 12982820 | D28: =E28-C28 -> -203999.25 | E28: ='Part-A & B_BOQ'!O2418 -> 12778820 | J28: 9511224 | L28: =D28-J28 -> -9715223.2
B29: Sub-Total - B | C29: =SUM(C21:C28) -> 8.0090648e+08 | D29: =SUM(D21:D28) -> -25178913 | E29: =SUM(E21:E28) -> 7.7572757e+08 | J29: =SUM(J21:J28) -> 833422225 | L29: =D29-J29 -> -8.5860114e+08
B30: Grand Toral (A + B) | C30: =C29+C19 -> 3.0604872e+09 | D30: =D29+D19 -> -31364949 | E30: =E29+E19 -> 3.0291223e+09
A31: C | B31: NT #01
A32: 1 | B32: Additional Aluminium Formwork | C32: =NT_01!F8 -> 1000000 | D32: =E32-C32 -> 0 | E32: =NT_01!F8 -> 1000000
B33: Sub-Total - C | C33: =SUM(C32) -> 1000000 | D33: =SUM(D32:D32) -> 0 | E33: =SUM(E32:E32) -> 1000000 | J33: =SUM(#REF!) -> #REF! | L33: =D33-J33 -> #REF!
A34: D | B34: NT #02 | C34: =NT_02!F21 -> 25404407 | D34: =E34-C34 -> 0 | E34: =NT_02!F21 -> 25404407 | J34: 1.2126816e+08 | L34: =D34-J34 -> -1.2126816e+08
B35: Sub-Total - D | C35: =SUM(C34:C34) -> 25404407 | D35: =SUM(D34:D34) -> 0 | E35: =SUM(E34:E34) -> 25404407 | J35: =SUM(J34:J34) -> 1.2126816e+08 | L35: =D35-J35 -> -1.2126816e+08
A36: E | B36: Derived Items (UPVC doors & Windows) | C36: ='Derived Items_UPVC'!F40 -> 1.0921928e+08 | D36: =E36-C36 -> 0 | E36: ='Derived Items_UPVC'!F40 -> 1.0921928e+08
B37: Sub-Total - E | C37: =SUM(C36:C36) -> 1.0921928e+08 | D37: =SUM(D36:D36) -> 0 | E37: =SUM(E36:E36) -> 1.0921928e+08
A38: F | B38: Derived Items (RMC & other Misc Works) | D38: =E38-C38 -> 41887062 | E38: ='Derived Items_RMC & Others'!O45 -> 41887062
B39: Sub-Total - F | C39: =SUM(C38:C38) -> 0 | D39: =SUM(D38:D38) -> 41887062 | E39: =SUM(E38:E38) -> 41887062
A40: G | B40: NT #03 | D40: =E40-C40 -> 8502749.3 | E40: =NT_03!J10 -> 8502749.3
B41: Sub-Total - G | C41: =SUM(C40:C40) -> 0 | D41: =SUM(D40:D40) -> 8502749.3 | E41: =SUM(E40:E40) -> 8502749.3
...

Sheet Part-A & B_BOQ
A1: BOQ FOR CIVIL & FINISHING WORKS
A2: Item No. | B2: Description of works | C2: UOM | D2: Rate | E2: As per VO#02 | K2: Current Variation | M2: As per Actual
E3: Quantity | H3: Amount (Rs.) | K3: Quantity | M3: Quantity | O3: Amount
E4: Ph - 1 | F4: Ph -2 | G4: Total | H4: Ph - 1 | I4: Ph -2 | J4: Total | K4: Ph 1 | L4: Ph 2 | M4: Ph 1 | N4: Ph 2
A5: A | B5: STRUCTURE WORKS
A7: 1 | B7: EARTHWORKS
B8: General Notes for all Excavation Items: Contractor shall take all required permissions from the appropriate authorities for Excavation, Blasting, Carting away materials etc. and shall bear all the expenses for the same.
B9: Rate shall include 1. Removal of all kinds of vegetation, small shrubs etc. If there are any shrubs, bushes, roots of the trees to be removed for min depth 1.5m including all necessary permissions. Lift & lead outside campus are to be considered to suit the local regulations. The necessary approval shall be taken for removal of trees with the consent of the clients if applicable. The contractor shall be fully responsible for liasoning with local authoritites, compliance to all the statutory obligations, including all labour lanes in force, facilities, policies etc. towards all employees , labour and under no circumstance nor any acting party pass on the responsiblitites of the contractor to the other contractor/clients.
B10: 2. Contractor shall get acquainted with site conditions, nature of soil and adopt suitable dewatering system as deemed fit for the nature of soil and prevailing water table and water collected by runoff or rain needs to be disposed off from the site. The rate shall include keeping the excavated surface dry till completion of the scope of work. Dewatered water/ Slush shall be drained out by suitable means to places not objected by civic authorities. The contractor shall submit the method statement for dewatering and the same shall be let out of the building premises through proper pipes & channels as required.
B11: 3. The rate shall include necessary general shoring, strutting with approved timber/steel accessories wherever necessary as approved by the Client / the Engineer.
B12: 4. Contour level to be taken jointly with the Project Manager and prior written approval be taken before starting any excavation/ filling at every 3 / 5 mt grids for arriving at the actual quantity using simpsons rule. Cost to include all and necessary royalty and other permission charges required to execute the works.
B13: 5. The rate shall include all necessary setting out of building, excavation line, barrication by grid/plot marking, survey by Total station, transfer of bench mark, etc., complete
B14: 6.The quoted rates includes seggregating of good quality excavated earth from the clay / silty soil and storing in designted area for further treatment within the site premises for future landscape purposes including preserving top 300 mm layer of existing soil to meet MOEF requirements.. No extra is payable towards double handling.
B15: 7. Quoted rates shall incldue the preparation of temporary access road / Pathways, cross over, foot path, tracks, hard standings, temporary ramp to approach the excavated level etc, and temporary drains, rerouting of existing roads, supporting systems for existing MEP services if any and re-routing if required, etc. complete. at no extra cost.
B16: 8. Carting away all types of excavated earth outside or within the site shall be included and environmental norms to be followed for discarding excavated material with submission of document of proof.
B17: 9. Soil shall be classified as three types for billing purpose.
B18: a.Classification under hard rock excavation item which requires chiselling with compressed air/mechanical equipment's,controlled blasting, chemical splitting, diamond cutting etc. with necessary mechanical equipment's and loose boulders which requires splitting and handling.
B19: b. Classification under soft/medium/ weathered rock excavation item which is non poclainable, can be excavated using rock breaker attachments to JCB/Poclain, manual chiselling, etc. and loose boulders removal without spliting etc.
... B25: 14. Qty. shall be arrived at after taking block levels taken prior to and after excavation. The below mentioned quantities are based on soil report and the quantities may vary as per site condition. Quantity mentioned is tentative and may vary to any extent depending upon underlying ground profile to be exposed during excavation.
A26: 1.01 | B26: INDIVIDUAL FOOTING / POCKET EXCAVATION
B27: Excavation in all types of soil including dense soil, laterite reddish brown/Laterite reddish brown with patches/ dense soildisintegrated/ weathered/ soft rock (Poclainable) for Footings / RAFT of columns, trenches for drains, etc., by mechanical means including manual excavation for levelling, dressing the edges, with all leads and lifts. Dewatering of both ground and surface water, removal of slurry generated while excavation and keeping the area free of water with necessary shoring, strutting, required for keeping earth in position etc, Note: PCC area shall be considered for measurement (Working space & provision of slopes if required for execution shall not be paid separately). Footings/ Rafts etc | C27: Cum | D27: 243 | E27: 2578.46 | F27: 1018.5 | G27: =SUM(E27:F27) -> 3596.96 | H27: =$D27*E27 -> 626565.78 | I27: =$D27*F27 -> 247495.5 | J27: =SUBTOTAL(9,H27:I27) -> 874061.28 | K27: =M27-E27 -> 9936.6924 | L27: =N27-F27 -> 5143.556 | M27: 12515.152 | N27: 6162.056 | O27: =(M27+N27)*$D27 -> 4538561.6
A28: 1.02 | B28: Specification & scope of work same as 1.01 but for Excavation in Hard rock / boulders (more than 1/2 Cum in size -Un poclainable) by chiselling/ wedging to required level for Raft, Footings of columns, Retaining walls, Core walls, catch pits, Lift pits,STP,UG tanks, trenches for drains, etc. to the required depth including all leads and lifts, dressing, grading, cleaning, excavating loose pockets directed and disposing etc. as per detailed specification and conforming to safety rules of Authority during the progress of work. Note: The percentage of voids to be deducted from stack measurement is 40% for hardrock or Initial levels will be taken before blasting hard rock and final levels will be taken after achieving required levels in presence of PIC. Note:PCC area shall be considered for measurement (Working space & provision of slopes if required for execution shall not be paid separately. Mode of measurement shall be by joint measurements/ levels before and after excavation). | C28: Cum | D28: 2774 | E28: 97 | F28: 48.5 | G28: =SUM(E28:F28) -> 145.5 | H28: =$D28*E28 -> 269078 | I28: =$D28*F28 -> 134539 | J28: =SUBTOTAL(9,H28:I28) -> 403617 | K28: =M28-E28 -> -97 | L28: =N28-F28 -> -48.5 | M28: 0 | N28: 0 | O28: =(M28+N28)*$D28 -> 0
A29: 1.02 | B29: BACKFILLING (with available earth) | D29: 0 | E29: 0 | F29: 0 | K29: =M29-E29 -> 0 | L29: =N29-F29 -> 0 | O29: =(M29+N29)*$D29 -> 0
B30: Supply and filling in foundations and the area whereever specified with approved good quality filling materials in plinths, area development etc. wherever specified in layers of not exceeding 150 mm thick including breaking clods,storing,transportation, double handling, watering, compacting each layer with vibratory compactor and at unaccessible places with wooden/steel rammers to achieve 90 to 95% proctor density at optimum moisture content, all leads and lifts, bailing/ pumping out of water to keep site dry while backfilling; cost shall include conveyance of all materials, labour, machinery etc. complete as directed.The rate to includes loading,unloading, hire and fuel charges for tools and plants and other incidental charges etc., complete. Cost to include all necessary royalty and other permission charges required to execute the works. With excavated earth available at site | C30: Cum | D30: 150 | E30: 15633.13 | F30: 2425 | G30: =SUM(E30:F30) -> 18058.13 | H30: =$D30*E30 -> 2344969.5 | I30: =$D30*F30 -> 363750 | J30: =SUBTOTAL(9,H30:I30) -> 2708719.5 | K30: =M30-E30 -> 0 | L30: =N30-F30 -> 0 | M30: 15633.13 | N30: 2425 | O30: =(M30+N30)*$D30 -> 2708719.5
A31: 1.03 | B31: Carting away surplus earth/excavated material/debris/rock and like materials outside the plot and disposing off the same to the designated areas identified by the local authorities / project managers for dumping of such material, including spreading, compacting etc.,as per the norms by the local authorities. Mode of measurement- where measurement is not possible by level. i) Soil - truck measurement less 20% for voids. ii) Hard Rock - truck measurement less 50% for voids iii) Debris - truck measurement less 30% for voids. | C31: Cum | D31: 278 | E31: 2425 | F31: 97 | G31: =SUM(E31:F31) -> 2522 | H31: =$D31*E31 -> 674150 | I31: =$D31*F31 -> 26966 | J31: =SUBTOTAL(9,H31:I31) -> 701116 | K31: =M31-E31 -> 0 | L31: =N31-F31 -> 0 | M31: 2425 | N31: 97 | O31: =(M31+N31)*$D31 -> 701116
E32: 0 | F32: 0 | K32: =M32-E32 -> 0 | L32: =N32-F32 -> 0 | O32: =(M32+N32)*$D32 -> 0
B33: Sub-Total | E33: 0 | F33: 0 | G33: 0 | H33: =SUM(H12:H32) -> 3914763.3 | I33: =SUM(I12:I32) -> 772750.5 | J33: =SUM(J12:J32) -> 4687513.8 | K33: =M33-E33 -> 0 | L33: =N33-F33 -> 0 | O33: =SUM(O12:O32) -> 7948397.1
A34: 2 | B34: ANTI-TERMITE TREATMENT WORKS | E34: 0 | F34: 0 | K34: =M34-E34 -> 0 | L34: =N34-F34 -> 0 | O34: =(M34+N34)*$D34 -> 0
A35: i | B35: Providing Pre-constructional anti- termite treatment and creating a chemical barrier to the building by injecting chemical emulsion of required concentrations under grade slab and Grade beam, around the Plinth, Plinth filling, trenches, junction of wall and floor, Retaining / side walls of basement floor, external perimeter of building, surrounding of pipes, expansion joints, below UG sump and etc.as per instructions of chemical manufacturer and all as directed. The treatment shall be carried out strictly in accordance with the technical specification and conforming to IS 6313 or equivalent BS specification. The chemical to be used as insecticides for the treatment shall be 50% EC (Imidacloprid 30.5 SC)and the application shall be dilute one part of chemical 50% EC with 49 parts of water to get 1% emulsion and strictly in accordance with the manufacturer's specification. Note : Measurement taken along external periphery of the building. Treatment shall extend to a width of 1m around the building. (Including 10 years warranty). | C35: Sqm | D35: 96 | E35: 10325.65 | F35: 1777.04 | G35: =SUM(E35:F35) -> 12102.69 | H35: =$D35*E35 -> 991262.4 | I35: =$D35*F35 -> 170595.84 | J35: =SUBTOTAL(9,H35:I35) -> 1161858.2 | K35: =M35-E35 -> 0 | L35: =N35-F35 -> 3484.542 | M35: 10325.65 | N35: 5261.582 | O35: =(M35+N35)*$D35 -> 1496374.3
E36: 0 | F36: 0 | G36: 0 | K36: =M36-E36 -> 0 | L36: =N36-F36 -> 0 | O36: =(M36+N36)*$D36 -> 0
B37: Sub-Total | E37: 0 | F37: 0 | G37: 0 | H37: =SUM(H35:H36) -> 991262.4 | I37: =SUM(I35:I36) -> 170595.84 | J37: =SUM(J35:J36) -> 1161858.2 | K37: =M37-E37 -> 0 | L37: =N37-F37 -> 0 | O37: =SUM(O35:O36) -> 1496374.3
E38: 0 | F38: 0 | G38: 0 | K38: =M38-E38 -> 0 | L38: =N38-F38 -> 0 | O38: =(M38+N38)*$D38 -> 0
A39: 2 | B39: PLAIN CEMENT CONCRETE WORKS | E39: 0 | F39: 0 | G39: 0 | J39: =SUM(H39+I39) -> 0 | K39: =M39-E39 -> 0 | L39: =N39-F39 -> 0 | O39: =(M39+N39)*$D39 -> 0
B40: Unless otherwise specified rates quoted for all PCC works shall include the following : | E40: 0 | F40: 0 | G40: 0 | J40: =SUM(H40+I40) -> 0 | K40: =M40-E40 -> 0 | L40: =N40-F40 -> 0 | O40: =(M40+N40)*$D40 -> 0
B41: Cost of all materials, labour, equipment / tools & plants required, lead and lifts, conveyance, infrastructure facilities required etc. | E41: 0 | F41: 0 | G41: 0 | J41: =SUM(H41+I41) -> 0 | K41: =M41-E41 -> 0 | L41: =N41-F41 -> 0 | O41: =(M41+N41)*$D41 -> 0
B42: The contractors are particularly advised to study the relevant drawings carefully before quoting. | E42: 0 | F42: 0 | G42: 0 | J42: =SUM(H42+I42) -> 0 | K42: =M42-E42 -> 0 | L42: =N42-F42 -> 0 | O42: =(M42+N42)*$D42 -> 0
B43: Minimum cement content for concrete shall be as per cement constants specified in the Technical specification. | E43: 0 | F43: 0 | G43: 0 | J43: =SUM(H43+I43) -> 0 | K43: =M43-E43 -> 0 | L43: =N43-F43 -> 0 | O43: =(M43+N43)*$D43 -> 0
B44: Cost of suitable form work as per site requirement. | E44: 0 | F44: 0 | G44: 0 | J44: =SUM(H44+I44) -> 0 | K44: =M44-E44 -> 0 | L44: =N44-F44 -> 0 | O44: =(M44+N44)*$D44 -> 0
B45: Adequate protection to edges and corners of Plain Cement Concrete works from damage during construction. | E45: 0 | F45: 0 | G45: 0 | J45: =SUM(H45+I45) -> 0 | K45: =M45-E45 -> 0 | L45: =N45-F45 -> 0 | O45: =(M45+N45)*$D45 -> 0
B46: Keeping the work, well watered for 3-5 days for plain cement concrete works after casting and it shall confirm to IS Specification. | E46: 0 | F46: 0 | G46: 0 | J46: =SUM(H46+I46) -> 0 | K46: =M46-E46 -> 0 | L46: =N46-F46 -> 0 | O46: =(M46+N46)*$D46 -> 0
...

Sheet Derived Items_RMC & Others
A1: Project - Provident Ecopolitan - Ph 1 & Ph 2
A2: Subject - Derived Items
A3: Item No. | B3: Description of works | C3: UOM | D3: Rate | E3: As per VO#02 | K3: Current Variation | M3: As per Actual
E4: Quantity | H4: Amount (Rs.) | K4: Quantity | M4: Quantity | O4: Amount
E5: Ph 1 | F5: Ph 2 | G5: Total Qty | H5: Ph - 1 | I5: Ph -2 | J5: Total | K5: Ph 1 | L5: Ph 2 | M5: Ph 1 | N5: Ph 2
B6: Derived Items | E6: 0 | F6: 0 | G6: 0 | H6: 0 | I6: 0 | J6: 0
A7: 3.2.1 | B7: Columns and Shear walls at all levels
B8: M40 grade (Item Description same as Sl No. 3.2.1 f)
A9: d | B9: 2nd floor | C9: Cum | D9: 7386 | E9: 0 | F9: 0 | G9: 0 | H9: 0 | I9: 0 | K9: =M9-E9 -> 371.51 | L9: =N9-F9 -> 0 | M9: 371.51 | N9: 0 | O9: =(M9+N9)*D9 -> 2743972.9
A10: e | B10: 3rd floor | C10: Cum | D10: 7386 | E10: 0 | F10: 0 | G10: 0 | H10: 0 | I10: 0 | K10: =M10-E10 -> 371.51 | L10: =N10-F10 -> 0 | M10: 371.51 | N10: 0 | O10: =(M10+N10)*D10 -> 2743972.9
A11: 3.2.2 | B11: Core Walls and Staircase walls at RCC core area in all levels | E11: 0 | F11: 0 | G11: 0 | H11: 0 | I11: 0 | K11: =M11-E11 -> 0 | L11: =N11-F11 -> 0 | M11: 0 | N11: 0 | O11: =(M11+N11)*D11 -> 0
B12: M30 Grade (Item Description same as Sl No. 3.2.2 i) | E12: 0 | F12: 0 | G12: 0 | H12: 0 | I12: 0 | K12: =M12-E12 -> 0 | L12: =N12-F12 -> 0 | M12: 0 | N12: 0 | O12: =(M12+N12)*D12 -> 0
A13: c | B13: 1st Floor | C13: Cum | D13: 7066 | E13: 0 | F13: 0 | G13: 0 | H13: 0 | I13: 0 | K13: =M13-E13 -> 0 | L13: =N13-F13 -> 67.951 | M13: 0 | N13: 67.951 | O13: =(M13+N13)*D13 -> 480141.77
A14: d | B14: 2nd Floor | C14: Cum | D14: 7066 | E14: 0 | F14: 0 | G14: 0 | H14: 0 | I14: 0 | K14: =M14-E14 -> 0 | L14: =N14-F14 -> 61.448 | M14: 0 | N14: 61.448 | O14: =(M14+N14)*D14 -> 434191.57
A15: e | B15: 3rd Floor | C15: Cum | D15: 7066 | E15: 0 | F15: 0 | G15: 0 | H15: 0 | I15: 0 | K15: =M15-E15 -> 0 | L15: =N15-F15 -> 61.448 | M15: 0 | N15: 61.448 | O15: =(M15+N15)*D15 -> 434191.57
A16: f | B16: 4th Floor | C16: Cum | D16: 7066 | E16: 0 | F16: 0 | G16: 0 | H16: 0 | I16: 0 | K16: =M16-E16 -> 0 | L16: =N16-F16 -> 61.448 | M16: 0 | N16: 61.448 | O16: =(M16+N16)*D16 -> 434191.57
A17: g | B17: 5th Floor | C17: Cum | D17: 7066 | E17: 0 | F17: 0 | G17: 0 | H17: 0 | I17: 0 | K17: =M17-E17 -> 0 | L17: =N17-F17 -> 61.448 | M17: 0 | N17: 61.448 | O17: =(M17+N17)*D17 -> 434191.57
A18: h | B18: 6th floor | C18: Cum | D18: 7066 | E18: 0 | F18: 0 | G18: 0 | H18: 0 | I18: 0 | K18: =M18-E18 -> 228.64467 | L18: =N18-F18 -> 61.448 | M18: 228.64467 | N18: 61.448 | O18: =(M18+N18)*D18 -> 2049794.8
A19: 3.2.3 | B19: RC Walls | E19: 0 | F19: 0 | G19: 0 | H19: 0 | I19: 0 | K19: =M19-E19 -> 0 | L19: =N19-F19 -> 0 | M19: 0 | N19: 0 | O19: =(M19+N19)*D19 -> 0
B20: M30 grade- (Item Description same as Sl No. 3.2.3 C) | E20: 0 | F20: 0 | G20: 0 | H20: 0 | I20: 0 | K20: =M20-E20 -> 0 | L20: =N20-F20 -> 0 | M20: 0 | N20: 0 | O20: =(M20+N20)*D20 -> 0
A21: a | B21: 1st floor | C21: Cum | D21: 7066 | E21: 0 | F21: 0 | G21: 0 | H21: 0 | I21: 0 | K21: =M21-E21 -> 620.38 | L21: =N21-F21 -> 380.45 | M21: 620.38 | N21: 380.45 | O21: =(M21+N21)*D21 -> 7071864.8
A22: b | B22: 2nd floor | C22: Cum | D22: 7066 | E22: 0 | F22: 0 | G22: 0 | H22: 0 | I22: 0 | K22: =M22-E22 -> 812.44 | L22: =N22-F22 -> 380.45 | M22: 812.44 | N22: 380.45 | O22: =(M22+N22)*D22 -> 8428960.7
A23: 3.2.4 | B23: Non Structural - RC Walls | E23: 0 | F23: 0 | G23: 0 | H23: 0 | I23: 0 | K23: =M23-E23 -> 0 | L23: =N23-F23 -> 0 | M23: 0 | N23: 0 | O23: =(M23+N23)*D23 -> 0
B24: M30 grade | E24: 0 | F24: 0 | G24: 0 | H24: 0 | I24: 0 | K24: =M24-E24 -> 0 | L24: =N24-F24 -> 0 | M24: 0 | N24: 0 | O24: =(M24+N24)*D24 -> 0
A25: a | B25: 1st floor | C25: Cum | D25: 7066 | E25: 0 | F25: 0 | G25: 0 | H25: 0 | I25: 0 | K25: =M25-E25 -> 66.73 | L25: =N25-F25 -> 26.19 | M25: 66.73 | N25: 26.19 | O25: =(M25+N25)*D25 -> 656572.72
A26: b | B26: 2nd floor | C26: Cum | D26: 7066 | E26: 0 | F26: 0 | G26: 0 | H26: 0 | I26: 0 | K26: =M26-E26 -> 89.31 | L26: =N26-F26 -> 26.19 | M26: 89.31 | N26: 26.19 | O26: =(M26+N26)*D26 -> 816123
A27: 3.2.1 | B27: MLCP Columns at all levels | E27: 0 | F27: 0 | G27: 0 | H27: 0 | I27: 0 | K27: =M27-E27 -> 0 | L27: =N27-F27 -> 0 | M27: 0 | N27: 0 | O27: =(M27+N27)*D27 -> 0
B28: M30 grade- (Item Description same as Sl No. 3.1.9) | E28: 0 | F28: 0 | G28: 0 | H28: 0 | I28: 0 | K28: =M28-E28 -> 0 | L28: =N28-F28 -> 0 | M28: 0 | N28: 0 | O28: =(M28+N28)*D28 -> 0
A29: g | B29: Foundation to Stilt | C29: Cum | D29: 7066 | E29: 0 | F29: 0 | G29: 0 | H29: 0 | I29: 0 | K29: =M29-E29 -> 316.286 | L29: =N29-F29 -> 86.666 | M29: 316.286 | N29: 86.666 | O29: =(M29+N29)*D29 -> 2847258.8
A30: h | B30: Stilt floor | C30: Cum | D30: 7066 | E30: 0 | F30: 0 | G30: 0 | H30: 0 | I30: 0 | K30: =M30-E30 -> 233.993 | L30: =N30-F30 -> 0 | M30: 233.993 | N30: 0 | O30: =(M30+N30)*D30 -> 1653394.5
A31: i | B31: 1st floor | C31: Cum | D31: 7066 | E31: 0 | F31: 0 | G31: 0 | H31: 0 | I31: 0 | K31: =M31-E31 -> 265.386 | L31: =N31-F31 -> 0 | M31: 265.386 | N31: 0 | O31: =(M31+N31)*D31 -> 1875217.5
A32: j | B32: 2nd floor | C32: Cum | D32: 7066 | E32: 0 | F32: 0 | G32: 0 | H32: 0 | I32: 0 | K32: =M32-E32 -> 249.386 | L32: =N32-F32 -> 0 | M32: 249.386 | N32: 0 | O32: =(M32+N32)*D32 -> 1762161.5
A33: k | B33: 3rd floor | C33: Cum | D33: 7066 | E33: 0 | F33: 0 | G33: 0 | H33: 0 | I33: 0 | K33: =M33-E33 -> 233.028 | L33: =N33-F33 -> 0 | M33: 233.028 | N33: 0 | O33: =(M33+N33)*D33 -> 1646575.8
A34: l | B34: 4th floor | C34: Cum | D34: 7066 | E34: 0 | F34: 0 | G34: 0 | H34: 0 | I34: 0 | K34: =M34-E34 -> 234.441 | L34: =N34-F34 -> 0 | M34: 234.441 | N34: 0 | O34: =(M34+N34)*D34 -> 1656560.1
A35: m | B35: 5th floor | C35: Cum | D35: 7066 | E35: 0 | F35: 0 | G35: 0 | H35: 0 | I35: 0 | K35: =M35-E35 -> 234.623 | L35: =N35-F35 -> 0 | M35: 234.623 | N35: 0 | O35: =(M35+N35)*D35 -> 1657846.1
A36: 9.5 | B36: UG SUMP | E36: 0 | F36: 0 | G36: 0 | H36: 0 | I36: 0 | K36: =M36-E36 -> 0 | L36: =N36-F36 -> 0 | M36: 0 | N36: 0 | O36: =(M36+N36)*D36 -> 0
A37: j | B37: 50∅ Puddle Flange | C37: Nos. | D37: 4500 | E37: 0 | F37: 0 | G37: 0 | H37: 0 | I37: 0 | K37: =M37-E37 -> 6 | L37: =N37-F37 -> 0 | M37: 6 | N37: 0 | O37: =(M37+N37)*D37 -> 27000
A38: k | B38: 65∅ Puddle Flange | C38: Nos. | D38: 5790 | E38: 0 | F38: 0 | G38: 0 | H38: 0 | I38: 0 | K38: =M38-E38 -> 2 | L38: =N38-F38 -> 0 | M38: 2 | N38: 0 | O38: =(M38+N38)*D38 -> 11580
A39: 9.6 | B39: STP WORKS | E39: 0 | F39: 0 | G39: 0 | H39: 0 | I39: 0 | K39: =M39-E39 -> 0 | L39: =N39-F39 -> 0 | M39: 0 | N39: 0 | O39: =(M39+N39)*D39 -> 0
A40: e | B40: Retail STP 50∅ Drain Out Pipe . length - 750mm-(Item Description same as Sl No. 9.4.2 I c) | C40: Nos. | D40: 4500 | E40: 0 | F40: 0 | G40: 0 | H40: 0 | I40: 0 | K40: =M40-E40 -> 1 | L40: =N40-F40 -> 0 | M40: 1 | N40: 0 | O40: =(M40+N40)*D40 -> 4500
...

Sheet Derived Items_UPVC
A1: Project - Provident Ecopolitan - Ph 1 & Ph 2
A2: Subject - UPVC DOORS & WINDOWS WORKS
A3: Item No. | B3: Description of works | C3: UOM | D3: Qty | E3: Rate / Sqm | F3: Amount (Rs.)
B5: Derived items for Sl.No. 7 (Finishing Works)
A6: 1 | B6: UPVC WORKS | D6: 0 | F6: =ROUND(E6*D6,0) -> 0
B7: Wind Pressure consideration:1.5Kpa (including factor of safety), fastners shall be of Hilti or fischer make, Water & Smoke test to be done, Glass shall come with Protection film which shall be removed during handing over. Actual Measurement to be taken at site for Windows/Doors opening. | D7: 0 | F7: =ROUND(E7*D7,0) -> 0
A8: 1.1 | B8: Providing and fixing in position glazed 2.5 track UPVC sliding doors provided with mosquito mesh of fiberglass mesh from saint gobain as per the drawing enclosed complete at all levels., consisting of sliding system, outer frames, shutter frames, all frame & shutter sections well reinforced as specified in the technical specifications etc assembled and fitted properly complete at all levels, The glass shall be of 6mm thk Clear toughened glass including anchoring frames as approved, fixing and other accessories, self locking handle of multi point locking as per the client/architect approval., heavy duty rollers and other hardware as required and as approved and all incidental work complete as per drawings and specifications. All the UPVC sections shall be finished in a fully automatic plant equipped for such work as per the specifications. Weather sealant of Dow corning/Momentive to be applied on the periphery of the window on both sides.Weather strip at every panel sides that restricts entry of mosquito and maintain temparature inside rooms, Shop drawing to be approved by the client prior to procurement/ supply of assembled widows to site. The EPDM gasket should be oven cured and neatly mitre joint at junctions.The drain/weep hole and its cover is also placed at required intervals that not allows water stagnates on trackes between and drains smoothly out. The complete system is well protected with films till final hand over. | D8: 0 | F8: =ROUND(E8*D8,0) -> 0
A9: 1.1.1 | B9: SD1 2100x2400 mm | C9: Sqm | D9: 3833.025 | E9: 4662 | F9: =E9*D9 -> 17869563
A10: 1.1.2 | B10: SD2 1800x2400 mm | C10: Sqm | D10: 4833.36 | E10: 4662 | F10: =E10*D10 -> 22533124
A11: 1.1.3 | B11: SD3 1600x2400 mm | C11: Sqm | D11: 1497.44 | E11: 4662 | F11: =E11*D11 -> 6981065.3
A12: 1.1.4 | B12: SD4 1500x2400 mm | C12: Sqm | D12: 312.375 | E12: 4662 | F12: =E12*D12 -> 1456292.2
A13: 1.1.5 | B13: SD4a 1525x2450 mm | C13: Sqm | D13: 14.945 | E13: 4662 | F13: =E13*D13 -> 69673.59
A14: 1.2 | B14: Providing & fixing 2.5 track UPVC glazed Sliding panel window consisting of 2 glazed panels with 6mm thk Clear glass and mosquito mesh and the window should have a provision for fixing of exhaust fan, all frame & shutter sections well reinforced as specified in the technical specifications etc as per the drawing enclosed complete at all levels. All the UPVC sections shall be finished in a fully automatic plant equipped for such work as per the specifications. Weather sealant of Dowcorning / Momentive to be applied on the periphery of the window on both sides.Weather strip at every panel sides that restricts entry of mosquito and maintain temparature inside rooms All Windows to be approved hardware by the architect/client. The movement of the sliding shutter should have smooth movement. colour ofthe single point lock to be as per the approvel of the client/architect. shop drawings to be approved prior to start of procurement/fabrication of windows. The EPDM gasket should be oven cured and neatly mitre joint at junctions.The drain/weep hole and its cover is also placed at required intervals that not allows water stagnates on trackes between and drains smoothly out. The complete system is well protected with films till final hand over. | D14: 0 | F14: =E14*D14 -> 0
A15: 1.2.1 | B15: KW1 1200x1300 mm | C15: Sqm | D15: 1577.16 | E15: 4662 | F15: =E15*D15 -> 7352719.9
A16: 1.2.2 | B16: KW2 1100x1300mm | C16: Sqm | D16: 45.76 | E16: 4662 | F16: =E16*D16 -> 213333.12
A17: 1.3 | B17: Providing & fixing of UPVC glazed window consisting of 2 glazed panels with 6 mm thk Clear glass at the bottom & top glass louvers as per the drawing enclosed complete at all levels. All the UPVC sections shall be finished in a fully automatic plant equipped for such work as per the specifications. all frame & shutter sections well reinforced as specified in the technical specifications etc Weather sealant of Dowcorning/Momentive to be applied on the periphery of the window on both sides. All Windows to be approved hardware by the architect/client. .Weather strip at every panel sides that restricts entry of mosquito and maintain temparature inside rooms. colour of the single point lock to be as per the approval of the client/architect. shop drawings to be approved prior to start of procurement/fabrication of windows. The EPDM gasket should be oven cured.and neatly mitre joint at junctions.The drain/weep hole and its cover is also placed at required intervals that not allows water stagnates on trackes between and drains smoothly out. The complete system is well protected with films till final hand over. Location: Staircase Areas | D17: 0 | F17: =E17*D17 -> 0
A18: 1.3.1 | B18: SW-1500X1500mm | C18: Sqm | D18: 904.5 | E18: 4662 | F18: =E18*D18 -> 4216779
A19: 1.3.2 | B19: SW1-1200X1500mm | C19: Sqm | D19: 358.2 | E19: 4662 | F19: =E19*D19 -> 1669928.4
A20: 1.3.3 | B20: SW3 - 900x1500mm | C20: Sqm | D20: 1.35 | E20: 4662 | F20: =E20*D20 -> 6293.7
A21: 1.3.4 | B21: SW1A 1200x1500mm | C21: Sqm | D21: 396 | E21: 4662 | F21: =E21*D21 -> 1846152
A22: 1.3.5 | B22: SW1B 1200x1500mm | C22: Sqm | D22: 3.6 | E22: 4662 | F22: =E22*D22 -> 16783.2
A23: 1.4 | B23: Providing & fixing 2.5track UPVC glazed window consisting of 2 glazed panels(Above portion opneable and bottom fixed, as per drawings) with 6mm thk Plain glass for windows for sliding portion and 6mm toughned clear glass for fixed portion. Mosquito mesh of fiberglass mesh from saint gobain to be fixed as per the drawing enclosed complete at all levels. All the UPVC sections shall be finished in a fully automatic plant equipped for such work as per the specifications. all frame & shutter sections well reinforced as specified in the technical specifications etc., Weather sealant of Dowcorning /Momentive to be applied on the periphery of the window on both sides. All Windows to be approved hardware by the architect/client. The movement of the sliding shutter should have smooth movement. colour ofthe single point lock to be as per the approval of the client/architect. Weather strip at every panel sides that restricts entry of mosquito and maintain temparature inside rooms shop drawings to be approved prior to start of procurement /fabrication of windows. The EPDM gasket should be oven cured and neatly mitre joint at junctions.The drain/weep hole and its cover is also placed at required intervals that not allows water stagnates on trackes between and drains smoothly out. The complete system is well protected with films till final hand over. | D23: 0 | F23: =E23*D23 -> 0
A24: 1.4.1 | B24: W1 2100x2325mm | C24: Sqm | D24: 810.495 | E24: 4662 | F24: =E24*D24 -> 3778527.7
A25: 1.4.2 | B25: W2 1800x2325 mm | C25: Sqm | D25: 133.92 | E25: 4662 | F25: =E25*D25 -> 624335.04
A26: 1.4.3 | B26: W3 1600x2325mm | C26: Sqm | D26: 777.48 | E26: 4662 | F26: =E26*D26 -> 3624611.8
A27: 1.4.4 | B27: W4 1500x2325mm | C27: Sqm | D27: 4083.8625 | E27: 4662 | F27: =E27*D27 -> 19038967
A28: 1.4.5 | B28: W4A 1525x2325mm | C28: Sqm | D28: 882.86063 | E28: 4662 | F28: =E28*D28 -> 4115896.2
A29: 1.4.6 | B29: W5 1400x2325mm | C29: Sqm | D29: 289.695 | E29: 4662 | F29: =E29*D29 -> 1350558.1
A30: 1.4.7 | B30: W6 1200x2325mm | C30: Sqm | D30: 345.96 | E30: 4662 | F30: =E30*D30 -> 1612865.5
A31: 1.4.8 | B31: W6A 1200x1500mm | C31: Sqm | D31: 39.6 | E31: 4662 | F31: =E31*D31 -> 184615.2
A32: 1.4.9 | B32: W7 500x1200mm | C32: Sqm | D32: 45 | E32: 4662 | F32: =E32*D32 -> 209790
A33: 1.4.10 | B33: W8 500x1200mm | C33: Sqm | D33: 39.6 | E33: 4662 | F33: =E33*D33 -> 184615.2
A34: 1.4.11 | B34: W9 1400X1200 mm | C34: Sqm | D34: 1.68 | E34: 4662 | F34: =E34*D34 -> 7832.16
A35: 1.4.12 | B35: W10 1500x1500mm | C35: Sqm | D35: 92.25 | E35: 4662 | F35: =E35*D35 -> 430069.5
A36: 1.5 | B36: Providing and fixing of UPVC ventilators with Architraves that rests at Internal flush with wall tiles of approved colour and sections. The ventilator should have a provision for fixing of exhaust fan and with fixed frosted glass louvers (4mm thickness), with all necessary accessories like handles, weep holes/covers, SS hinges, lock, screws etc., complete at all levels as pe architect/Client approval. Weather sealant outside/Sanitary grade selant at inside around frames / architraves of Dow corning/Momentive to be applied on the periphery of the window on both sides. | D36: 0 | F36: =E36*D36 -> 0
A37: 1.5.1 | B37: V1 750x1200 mm | C37: Sqm | D37: 1905.3 | E37: 4662 | F37: =E37*D37 -> 8882508.6
A38: 1.5.2 | B38: V3 600x750mm | C38: Sqm | D38: 88.2 | E38: 4662 | F38: =E38*D38 -> 411188.4
A39: 1.5.3 | B39: V2 600x900 mm | C39: Sqm | D39: 113.94 | E39: 4662 | F39: =E39*D39 -> 531188.28
B40: Total Amount (Excl GST) | D40: =SUM(D7:D39) -> 23427.558 | F40: =SUM(F7:F39) -> 1.0921928e+08

Sheet Working_UPVC
A2: DERIVED ITEMS
E3: As per LOA | K3: Current Variation | M3: As per VO#02
A4: Item No. | B4: Description of works | C4: UOM | D4: Rate | E4: Quantity | H4: Amount (Rs.) | K4: Quantity | M4: Quantity | O4: Amount
E5: Ph - 1 | F5: Ph -2 | G5: Total Qty | H5: Ph - 1 | I5: Ph -2 | J5: Total | K5: Ph - 1 | L5: Ph -2 | M5: Ph - 1 | N5: Ph -2 | O5: Ph - 1 | P5: Ph -2 | Q5: Sqm | R5: Nos
A6: 7 | B6: UPVC WORKS | E6: 0 | F6: 0 | G6: =SUM(E6:F6) -> 0 | H6: =ROUND(D6*E6,0) -> 0 | I6: =ROUND(D6*F6,0) -> 0 | J6: =SUM(H6:I6) -> 0
B7: Wind Pressure consideration:1.5Kpa (including factor of safety), fastners shall be of Hilti or fischer make, Water & Smoke test to be done, Glass shall come with Protection film which shall be removed during handing over. Actual Measurement to be taken at site for Windows/Doors opening. | E7: 0 | F7: 0 | G7: =SUM(E7:F7) -> 0 | H7: =ROUND(D7*E7,0) -> 0 | I7: =ROUND(D7*F7,0) -> 0 | J7: =SUM(H7:I7) -> 0 | Q7: =N7+M7 -> 0
A8: 7.1 | B8: Providing and fixing in position glazed 2.5 track UPVC sliding doors provided with mosquito mesh of fiberglass mesh from saint gobain as per the drawing enclosed complete at all levels., consisting of sliding system, outer frames, shutter frames, all frame & shutter sections well reinforced as specified in the technical specifications etc assembled and fitted properly complete at all levels, The glass shall be of 6mm thk Clear toughened glass including anchoring frames as approved, fixing and other accessories, self locking handle of multi point locking as per the client/architect approval., heavy duty rollers and other hardware as required and as approved and all incidental work complete as per drawings and specifications. All the UPVC sections shall be finished in a fully automatic plant equipped for such work as per the specifications. Weather sealant of Dow corning/Momentive to be applied on the periphery of the window on both sides.Weather strip at every panel sides that restricts entry of mosquito and maintain temparature inside rooms, Shop drawing to be approved by the client prior to procurement/ supply of assembled widows to site. The EPDM gasket should be oven cured and neatly mitre joint at junctions.The drain/weep hole and its cover is also placed at required intervals that not allows water stagnates on trackes between and drains smoothly out. The complete system is well protected with films till final hand over. | E8: 0 | F8: 0 | G8: =SUM(E8:F8) -> 0 | H8: =ROUND(D8*E8,0) -> 0 | I8: =ROUND(D8*F8,0) -> 0 | J8: =SUM(H8:I8) -> 0 | Q8: =N8+M8 -> 0
A9: 7.1.1 | B9: SD1 2100x2400 mm | D9: 0 | E9: 0 | F9: 0 | G9: =SUM(E9:F9) -> 0 | H9: =ROUND(D9*E9,0) -> 0 | I9: =ROUND(D9*F9,0) -> 0 | J9: =SUM(H9:I9) -> 0 | Q9: =N9+M9 -> 0
A10: a | B10: Floor -1 | C10: Sqm | D10: 4662 | E10: 111.55 | F10: 65.96 | G10: =SUM(E10:F10) -> 177.51 | H10: =$D10*E10 -> 520046.1 | I10: =$D10*F10 -> 307505.52 | J10: =SUBTOTAL(9,H10:I10) -> 827551.62 | K10: =M10-E10 -> -0.67 | L10: =N10-F10 -> 0 | M10: 110.88 | N10: 65.96 | O10: =M10*D10 -> 516922.56 | P10: =N10*D10 -> 307505.52 | Q10: =N10+M10 -> 176.84 | R10: =Q10/(2.1*2.4) -> 35.087302
A11: b | B11: Floor -2 | C11: Sqm | D11: 4662 | E11: 131.92 | F11: 61.11 | G11: =SUM(E11:F11) -> 193.03 | H11: =$D11*E11 -> 615011.04 | I11: =$D11*F11 -> 284894.82 | J11: =SUBTOTAL(9,H11:I11) -> 899905.86 | K11: =M11-E11 -> -0.88 | L11: =N11-F11 -> 0 | M11: 131.04 | N11: 61.11 | O11: =M11*D11 -> 610908.48 | P11: =N11*D11 -> 284894.82 | Q11: =N11+M11 -> 192.15 | R11: =Q11/(2.1*2.4) -> 38.125
A12: c | B12: Floor -3 | C12: Sqm | D12: 4662 | E12: 131.92 | F12: 61.11 | G12: =SUM(E12:F12) -> 193.03 | H12: =$D12*E12 -> 615011.04 | I12: =$D12*F12 -> 284894.82 | J12: =SUBTOTAL(9,H12:I12) -> 899905.86 | K12: =M12-E12 -> -0.88 | L12: =N12-F12 -> 0 | M12: 131.04 | N12: 61.11 | O12: =M12*D12 -> 610908.48 | P12: =N12*D12 -> 284894.82 | Q12: =N12+M12 -> 192.15 | R12: =Q12/(2.1*2.4) -> 38.125
A13: d | B13: Floor -4 | C13: Sqm | D13: 4662 | E13: 131.92 | F13: 61.11 | G13: =SUM(E13:F13) -> 193.03 | H13: =$D13*E13 -> 615011.04 | I13: =$D13*F13 -> 284894.82 | J13: =SUBTOTAL(9,H13:I13) -> 899905.86 | K13: =M13-E13 -> -0.88 | L13: =N13-F13 -> 0 | M13: 131.04 | N13: 61.11 | O13: =M13*D13 -> 610908.48 | P13: =N13*D13 -> 284894.82 | Q13: =N13+M13 -> 192.15 | R13: =Q13/(2.1*2.4) -> 38.125
A14: e | B14: Floor -5 | C14: Sqm | D14: 4662 | E14: 131.92 | F14: 61.11 | G14: =SUM(E14:F14) -> 193.03 | H14: =$D14*E14 -> 615011.04 | I14: =$D14*F14 -> 284894.82 | J14: =SUBTOTAL(9,H14:I14) -> 899905.86 | K14: =M14-E14 -> -0.88 | L14: =N14-F14 -> 0 | M14: 131.04 | N14: 61.11 | O14: =M14*D14 -> 610908.48 | P14: =N14*D14 -> 284894.82 | Q14: =N14+M14 -> 192.15 | R14: =Q14/(2.1*2.4) -> 38.125
A15: f | B15: Floor -6 | C15: Sqm | D15: 4662 | E15: 198.85 | F15: 61.11 | G15: =SUM(E15:F15) -> 259.96 | H15: =$D15*E15 -> 927038.7 | I15: =$D15*F15 -> 284894.82 | J15: =SUBTOTAL(9,H15:I15) -> 1211933.5 | K15: =M15-E15 -> -2.29 | L15: =N15-F15 -> 0 | M15: 196.56 | N15: 61.11 | O15: =M15*D15 -> 916362.72 | P15: =N15*D15 -> 284894.82 | Q15: =N15+M15 -> 257.67 | R15: =Q15/(2.1*2.4) -> 51.125
A16: g | B16: Floor -7 | C16: Sqm | D16: 4662 | E16: 198.85 | F16: 61.11 | G16: =SUM(E16:F16) -> 259.96 | H16: =$D16*E16 -> 927038.7 | I16: =$D16*F16 -> 284894.82 | J16: =SUBTOTAL(9,H16:I16) -> 1211933.5 | K16: =M16-E16 -> -2.29 | L16: =N16-F16 -> 0 | M16: 196.56 | N16: 61.11 | O16: =M16*D16 -> 916362.72 | P16: =N16*D16 -> 284894.82 | Q16: =N16+M16 -> 257.67 | R16: =Q16/(2.1*2.4) -> 51.125
A17: h | B17: Floor -8 | C17: Sqm | D17: 4662 | E17: 198.85 | F17: 61.11 | G17: =SUM(E17:F17) -> 259.96 | H17: =$D17*E17 -> 927038.7 | I17: =$D17*F17 -> 284894.82 | J17: =SUBTOTAL(9,H17:I17) -> 1211933.5 | K17: =M17-E17 -> -2.29 | L17: =N17-F17 -> 0 | M17: 196.56 | N17: 61.11 | O17: =M17*D17 -> 916362.72 | P17: =N17*D17 -> 284894.82 | Q17: =N17+M17 -> 257.67 | R17: =Q17/(2.1*2.4) -> 51.125
A18: i | B18: Floor -9 | C18: Sqm | D18: 4662 | E18: 198.85 | F18: 61.11 | G18: =SUM(E18:F18) -> 259.96 | H18: =$D18*E18 -> 927038.7 | I18: =$D18*F18 -> 284894.82 | J18: =SUBTOTAL(9,H18:I18) -> 1211933.5 | K18: =M18-E18 -> -2.29 | L18: =N18-F18 -> 0 | M18: 196.56 | N18: 61.11 | O18: =M18*D18 -> 916362.72 | P18: =N18*D18 -> 284894.82 | Q18: =N18+M18 -> 257.67 | R18: =Q18/(2.1*2.4) -> 51.125
A19: j | B19: Floor -10 | C19: Sqm | D19: 4662 | E19: 198.85 | F19: 61.11 | G19: =SUM(E19:F19) -> 259.96 | H19: =$D19*E19 -> 927038.7 | I19: =$D19*F19 -> 284894.82 | J19: =SUBTOTAL(9,H19:I19) -> 1211933.5 | K19: =M19-E19 -> -2.29 | L19: =N19-F19 -> 0 | M19: 196.56 | N19: 61.11 | O19: =M19*D19 -> 916362.72 | P19: =N19*D19 -> 284894.82 | Q19: =N19+M19 -> 257.67 | R19: =Q19/(2.1*2.4) -> 51.125
A20: k | B20: Floor -11 | C20: Sqm | D20: 4662 | E20: 198.85 | F20: 61.11 | G20: =SUM(E20:F20) -> 259.96 | H20: =$D20*E20 -> 927038.7 | I20: =$D20*F20 -> 284894.82 | J20: =SUBTOTAL(9,H20:I20) -> 1211933.5 | K20: =M20-E20 -> -2.29 | L20: =N20-F20 -> 0 | M20: 196.56 | N20: 61.11 | O20: =M20*D20 -> 916362.72 | P20: =N20*D20 -> 284894.82 | Q20: =N20+M20 -> 257.67 | R20: =Q20/(2.1*2.4) -> 51.125
A21: l | B21: Floor -12 | C21: Sqm | D21: 4662 | E21: 198.85 | F21: 61.11 | G21: =SUM(E21:F21) -> 259.96 | H21: =$D21*E21 -> 927038.7 | I21: =$D21*F21 -> 284894.82 | J21: =SUBTOTAL(9,H21:I21) -> 1211933.5 | K21: =M21-E21 -> -2.29 | L21: =N21-F21 -> 0 | M21: 196.56 | N21: 61.11 | O21: =M21*D21 -> 916362.72 | P21: =N21*D21 -> 284894.82 | Q21: =N21+M21 -> 257.67 | R21: =Q21/(2.1*2.4) -> 51.125
... A28: s | B28: Floor -19 | C28: Sqm | D28: 4662 | E28: 198.85 | F28: 61.11 | G28: =SUM(E28:F28) -> 259.96 | H28: =$D28*E28 -> 927038.7 | I28: =$D28*F28 -> 284894.82 | J28: =SUBTOTAL(9,H28:I28) -> 1211933.5 | K28: =M28-E28 -> -2.29 | L28: =N28-F28 -> 0 | M28: 196.56 | N28: 61.11 | O28: =M28*D28 -> 916362.72 | P28: =N28*D28 -> 284894.82 | Q28: =N28+M28 -> 257.67 | R28: =Q28/(2.1*2.4) -> 51.125
A29: t | B29: Floor -20 | C29: Sqm | D29: 4662 | E29: 0 | F29: 61.11 | G29: =SUM(E29:F29) -> 61.11 | H29: =$D29*E29 -> 0 | I29: =$D29*F29 -> 284894.82 | J29: =SUBTOTAL(9,H29:I29) -> 284894.82 | K29: =M29-E29 -> 0 | L29: =N29-F29 -> 0 | N29: 61.11 | O29: =M29*D29 -> 0 | P29: =N29*D29 -> 284894.82 | Q29: =N29+M29 -> 61.11 | R29: =Q29/(2.1*2.4) -> 12.125
A30: u | B30: Floor -21 | C30: Sqm | D30: 4662 | E30: 0 | F30: 35.89 | G30: =SUM(E30:F30) -> 35.89 | H30: =$D30*E30 -> 0 | I30: =$D30*F30 -> 167319.18 | J30: =SUBTOTAL(9,H30:I30) -> 167319.18 | K30: =M30-E30 -> 0 | L30: =N30-F30 -> 0 | N30: 35.89 | O30: =M30*D30 -> 0 | P30: =N30*D30 -> 167319.18 | Q30: =N30+M30 -> 35.89 | R30: =Q30/(2.1*2.4) -> 7.1210317
A31: v | B31: Floor -22 | C31: Sqm | D31: 4662 | E31: 0 | F31: 35.89 | G31: =SUM(E31:F31) -> 35.89 | H31: =$D31*E31 -> 0 | I31: =$D31*F31 -> 167319.18 | J31: =SUBTOTAL(9,H31:I31) -> 167319.18 | K31: =M31-E31 -> 0 | L31: =N31-F31 -> 0 | N31: 35.89 | O31: =M31*D31 -> 0 | P31: =N31*D31 -> 167319.18 | Q31: =N31+M31 -> 35.89 | R31: =Q31/(2.1*2.4) -> 7.1210317
A32: w | B32: Terrace Floor | C32: Sqm | D32: 4662 | E32: 0 | F32: 0 | G32: =SUM(E32:F32) -> 0 | H32: =$D32*E32 -> 0 | I32: =$D32*F32 -> 0 | J32: =SUBTOTAL(9,H32:I32) -> 0 | K32: =M32-E32 -> 0 | L32: =N32-F32 -> 0 | O32: =M32*D32 -> 0 | P32: =N32*D32 -> 0 | Q32: =N32+M32 -> 0
A33: 7.1.2 | B33: SD2 1800x2400 mm | D33: 0 | E33: 0 | F33: 0 | G33: =SUM(E33:F33) -> 0 | H33: =ROUND(D33*E33,0) -> 0 | I33: =ROUND(D33*F33,0) -> 0 | J33: =SUM(H33:I33) -> 0 | K33: =M33-E33 -> 0 | L33: =N33-F33 -> 0 | O33: =M33*D33 -> 0 | P33: =N33*D33 -> 0 | Q33: =N33+M33 -> 0
A34: a | B34: Floor -1 | C34: Sqm | D34: 4662 | E34: 45.59 | F34: 27.16 | G34: =SUM(E34:F34) -> 72.75 | H34: =$D34*E34 -> 212540.58 | I34: =$D34*F34 -> 126619.92 | J34: =SUBTOTAL(9,H34:I34) -> 339160.5 | K34: =M34-E34 -> -2.3 | L34: =N34-F34 -> 0 | M34: 43.29 | N34: 27.16 | O34: =M34*D34 -> 201817.98 | P34: =N34*D34 -> 126619.92 | Q34: =N34+M34 -> 70.45
A35: b | B35: Floor -2 | C35: Sqm | D35: 4662 | E35: 93.12 | F35: 27.16 | G35: =SUM(E35:F35) -> 120.28 | H35: =$D35*E35 -> 434125.44 | I35: =$D35*F35 -> 126619.92 | J35: =SUBTOTAL(9,H35:I35) -> 560745.36 | K35: =M35-E35 -> -1.95 | L35: =N35-F35 -> 0 | M35: 91.17 | N35: 27.16 | O35: =M35*D35 -> 425034.54 | P35: =N35*D35 -> 126619.92 | Q35: =N35+M35 -> 118.33
A36: c | B36: Floor -3 | C36: Sqm | D36: 4662 | E36: 93.12 | F36: 27.16 | G36: =SUM(E36:F36) -> 120.28 | H36: =$D36*E36 -> 434125.44 | I36: =$D36*F36 -> 126619.92 | J36: =SUBTOTAL(9,H36:I36) -> 560745.36 | K36: =M36-E36 -> -6.27 | L36: =N36-F36 -> 0 | M36: 86.85 | N36: 27.16 | O36: =M36*D36 -> 404894.7 | P36: =N36*D36 -> 126619.92 | Q36: =N36+M36 -> 114.01
A37: d | B37: Floor -4 | C37: Sqm | D37: 4662 | E37: 93.12 | F37: 27.16 | G37: =SUM(E37:F37) -> 120.28 | H37: =$D37*E37 -> 434125.44 | I37: =$D37*F37 -> 126619.92 | J37: =SUBTOTAL(9,H37:I37) -> 560745.36 | K37: =M37-E37 -> -6.27 | L37: =N37-F37 -> 0 | M37: 86.85 | N37: 27.16 | O37: =M37*D37 -> 404894.7 | P37: =N37*D37 -> 126619.92 | Q37: =N37+M37 -> 114.01
A38: e | B38: Floor -5 | C38: Sqm | D38: 4662 | E38: 93.12 | F38: 27.16 | G38: =SUM(E38:F38) -> 120.28 | H38: =$D38*E38 -> 434125.44 | I38: =$D38*F38 -> 126619.92 | J38: =SUBTOTAL(9,H38:I38) -> 560745.36 | K38: =M38-E38 -> -6.27 | L38: =N38-F38 -> 0 | M38: 86.85 | N38: 27.16 | O38: =M38*D38 -> 404894.7 | P38: =N38*D38 -> 126619.92 | Q38: =N38+M38 -> 114.01
A39: f | B39: Floor -6 | C39: Sqm | D39: 4662 | E39: 137.74 | F39: 27.16 | G39: =SUM(E39:F39) -> 164.9 | H39: =$D39*E39 -> 642143.88 | I39: =$D39*F39 -> 126619.92 | J39: =SUBTOTAL(9,H39:I39) -> 768763.8 | K39: =M39-E39 -> -3.37 | L39: =N39-F39 -> 0 | M39: 134.37 | N39: 27.16 | O39: =M39*D39 -> 626432.94 | P39: =N39*D39 -> 126619.92 | Q39: =N39+M39 -> 161.53
A40: g | B40: Floor -7 | C40: Sqm | D40: 4662 | E40: 137.74 | F40: 27.16 | G40: =SUM(E40:F40) -> 164.9 | H40: =$D40*E40 -> 642143.88 | I40: =$D40*F40 -> 126619.92 | J40: =SUBTOTAL(9,H40:I40) -> 768763.8 | K40: =M40-E40 -> -3.37 | L40: =N40-F40 -> 0 | M40: 134.37 | N40: 27.16 | O40: =M40*D40 -> 626432.94 | P40: =N40*D40 -> 126619.92 | Q40: =N40+M40 -> 161.53
A41: h | B41: Floor -8 | C41: Sqm | D41: 4662 | E41: 137.74 | F41: 27.16 | G41: =SUM(E41:F41) -> 164.9 | H41: =$D41*E41 -> 642143.88 | I41: =$D41*F41 -> 126619.92 | J41: =SUBTOTAL(9,H41:I41) -> 768763.8 | K41: =M41-E41 -> -3.37 | L41: =N41-F41 -> 0 | M41: 134.37 | N41: 27.16 | O41: =M41*D41 -> 626432.94 | P41: =N41*D41 -> 126619.92 | Q41: =N41+M41 -> 161.53
A42: i | B42: Floor -9 | C42: Sqm | D42: 4662 | E42: 137.74 | F42: 27.16 | G42: =SUM(E42:F42) -> 164.9 | H42: =$D42*E42 -> 642143.88 | I42: =$D42*F42 -> 126619.92 | J42: =SUBTOTAL(9,H42:I42) -> 768763.8 | K42: =M42-E42 -> -3.37 | L42: =N42-F42 -> 0 | M42: 134.37 | N42: 27.16 | O42: =M42*D42 -> 626432.94 | P42: =N42*D42 -> 126619.92 | Q42: =N42+M42 -> 161.53
A43: j | B43: Floor -10 | C43: Sqm | D43: 4662 | E43: 137.74 | F43: 27.16 | G43: =SUM(E43:F43) -> 164.9 | H43: =$D43*E43 -> 642143.88 | I43: =$D43*F43 -> 126619.92 | J43: =SUBTOTAL(9,H43:I43) -> 768763.8 | K43: =M43-E43 -> -3.37 | L43: =N43-F43 -> 0 | M43: 134.37 | N43: 27.16 | O43: =M43*D43 -> 626432.94 | P43: =N43*D43 -> 126619.92 | Q43: =N43+M43 -> 161.53
A44: k | B44: Floor -11 | C44: Sqm | D44: 4662 | E44: 137.74 | F44: 27.16 | G44: =SUM(E44:F44) -> 164.9 | H44: =$D44*E44 -> 642143.88 | I44: =$D44*F44 -> 126619.92 | J44: =SUBTOTAL(9,H44:I44) -> 768763.8 | K44: =M44-E44 -> -3.37 | L44: =N44-F44 -> 0 | M44: 134.37 | N44: 27.16 | O44: =M44*D44 -> 626432.94 | P44: =N44*D44 -> 126619.92 | Q44: =N44+M44 -> 161.53
A45: l | B45: Floor -12 | C45: Sqm | D45: 4662 | E45: 137.74 | F45: 27.16 | G45: =SUM(E45:F45) -> 164.9 | H45: =$D45*E45 -> 642143.88 | I45: =$D45*F45 -> 126619.92 | J45: =SUBTOTAL(9,H45:I45) -> 768763.8 | K45: =M45-E45 -> -3.37 | L45: =N45-F45 -> 0 | M45: 134.37 | N45: 27.16 | O45: =M45*D45 -> 626432.94 | P45: =N45*D45 -> 126619.92 | Q45: =N45+M45 -> 161.53
... A56: w | B56: Terrace Floor | C56: Sqm | D56: 4662 | E56: 0 | F56: 0 | G56: =SUM(E56:F56) -> 0 | H56: =$D56*E56 -> 0 | I56: =$D56*F56 -> 0 | J56: =SUBTOTAL(9,H56:I56) -> 0 | K56: =M56-E56 -> 0 | L56: =N56-F56 -> 0 | M56: 0 | N56: 0 | O56: =M56*D56 -> 0 | P56: =N56*D56 -> 0 | Q56: =N56+M56 -> 0
A57: 7.1.3 | B57: SD3 1600x2400 mm | D57: 0 | E57: 0 | F57: 0 | G57: =SUM(E57:F57) -> 0 | H57: =ROUND(D57*E57,0) -> 0 | I57: =ROUND(D57*F57,0) -> 0 | J57: =SUM(H57:I57) -> 0 | K57: =M57-E57 -> 0 | L57: =N57-F57 -> 0 | O57: =M57*D57 -> 0 | P57: =N57*D57 -> 0 | Q57: =N57+M57 -> 0
...

Sheet NT_01
A3: BOQ FOR NON TENDERED ITEMS #01
A4: Item No. | B4: Description of works | C4: UOM | D4: Qty | E4: Rate | F4: Amount (Rs.)
A5: B | B5: NT Items
A6: B.1 | B6: Additional aluminium formwork for nib walls (Extra rate over and above existing BOQ line item)
A7: B.1.1 | B7: Extra rate over and above existing BOQ line item for mobilisation, providing and demobilisation of Additional aluminium modular formwork due to design change for nib walls. | C7: LS | D7: 1 | E7: 10,00,000 | F7: 10,00,000
A8: Total Amount (Excl GST) | F8: 1000000

Sheet NT_02
A1: Project : Provident Ecopolitan-Phase-01
A2: Subject : BOQ for NT Items #02
A4: Sl.No | B4: Description | C4: Unit | D4: Qty | E4: Rate | F4: Amount | G4: Remarks
B6: NT-Items Set # 02 Phase-01
A7: 1 | B7: Providing & filling Plumbing Groove with M15 Grade 1:2:4 in Kitchen,Utility & Toilets,Width considered 50 to 75MM Complete as directed by the Architects / Engineer in charge. | C7: Rmt | D7: 22830.033 | E7: 170 | F7: =$D7*E7 -> 3881105.6
A8: 2 | B8: Providing & fixing Reinforcement Steel of 8mm Dia (150mm deep)TMT bar with Hilti HY 200 R chemical including drilling of required size hole and fixing complete in all respect for all height and depths ( Reinforcement steel Excluded) | C8: Nos | D8: 127 | E8: 212 | F8: =$D8*E8 -> 26924
A9: 3 | B9: Providing & fixing Reinforcement Steel of 10mm dia (150mm deep)TMT bar with Hilti HY 200 R chemical including drilling of required size hole and fixing complete in all respect for all height and depths ( Reinforcement steel Excluded) | C9: Nos | D9: 138 | E9: 250 | F9: =$D9*E9 -> 34500
A10: 4 | B10: Providing & fixing Reinforcement Steel of 12mm Dia (150mm deep)TMT bar with Hilti HY 200 R chemical including drilling of required size hole and fixing complete in all respect for all height and depths ( Reinforcement steel Excluded) | C10: Nos | D10: 134 | E10: 365 | F10: =$D10*E10 -> 48910
A11: 5 | B11: Providing & fixing Reinforcement Steel of 16mm Dia (150mm deep)TMT bar with Hilti HY 200 R chemical including drilling of required size hole and fixing complete in all respect for all height and depths ( Reinforcement steel Excluded) | C11: Nos | D11: 318 | E11: 535 | F11: =$D11*E11 -> 170130
